<?xml version="1.0" ?>
<!-- =================================================================================== -->
<!-- |    This document was autogenerated by xacro from walker.xacro                   | -->
<!-- |    EDITING THIS FILE BY HAND IS NOT RECOMMENDED                                 | -->
<!-- =================================================================================== -->
<robot name="walker" 
  xmlns:xacro="http://www.ros.org/wiki/xacro">
  <gazebo>
    <plugin filename="libgazebo_ros_control.so" name="gazebo_ros_control">
      <robotNamespace>/walker</robotNamespace>
      <robotSimType>gazebo_ros_control/DefaultRobotHWSim</robotSimType>
    </plugin>
  </gazebo>
  <link name="world"/>
  <joint name="world_joint1" type="prismatic">
    <parent link="world"/>
    <child link="world1"/>
    <origin rpy="0.0 0.0 0.0" xyz="0.0 0.0 0.0"/>
    <calibration rising="0.0"/>
    <dynamics damping="0.0" friction="0.0"/>
    <limit effort="100" lower="-100" upper="100" velocity="100"/>
  </joint>
  <link name="world1"/>

  <joint name="world_joint2" type="prismatic">
    <parent link="world1"/>
    <child link="world2"/>
    <origin rpy="0.0 0.0 1.5708" xyz="0.0 0.0 0.0"/>
    <calibration rising="0.0"/>
    <dynamics damping="0.0" friction="0.0"/>
    <limit effort="100" lower="-100" upper="100" velocity="100"/>
  </joint>
  <link name="world2"/>

  <joint name="world_joint3" type="prismatic">
    <parent link="world2"/>
    <child link="world3"/>
    <origin rpy="0.0 -1.5708 0.0" xyz="0.0 0.0 0.0"/>
    <calibration rising="0.0"/>
    <dynamics damping="0.0" friction="0.0"/>
    <limit effort="100" lower="-100" upper="100" velocity="100"/>
  </joint>
  <link name="world3"/>

  <joint name="world_joint4" type="continuous">
    <parent link="world3"/>
    <child link="world4"/>
    <origin rpy="0.0 0.0 0.0" xyz="1.15 0.0 0.0"/>
    <calibration rising="0.0"/>
    <dynamics damping="0.0" friction="0.0"/>
  </joint>
  <link name="world4"/>


  <joint name="world_joint5" type="continuous">
    <parent link="world4"/>
    <child link="world5"/>
    <origin rpy="0.0 1.5708 0.0" xyz="0.0 0.0 0.0"/>
    <calibration rising="0.0"/>
    <dynamics damping="0.0" friction="0.0"/>
  </joint>
  <link name="world5"/>


  <joint name="world_joint6" type="continuous">
    <parent link="world5"/>
    <child link="world6"/>
    <origin rpy="0.0 0.0 -1.5708" xyz="0.0 0.0 0.0"/>
    <calibration rising="0.0"/>
    <dynamics damping="0.0" friction="0.0"/>
  </joint>

  <link name="world6"/>

  <joint name="world_joint7" type="fixed">
    <parent link="world6"/>
    <child link="base_link"/>
    <origin rpy="0.0 0.0 0.0" xyz="0.0 0.0 0.0"/>
  </joint>
  <!-- <joint name="world_joint" type="fixed">
    <parent link="world"/>
    <child link="base_link"/>
    <origin rpy="0.0 0.0 0.0" xyz="0.0 0.0 1.15"/>
  </joint> -->
  <!-- <joint name="world_joint1" type="continuous">
    <parent link="world"/>
    <child link="base_link"/>
    <origin rpy="-1.5708 0.0 0.0" xyz="0.0 0.0 0.0"/>
    <calibration rising="0.0"/>
    <dynamics damping="0.0" friction="0.0"/>
  </joint> -->
  <link name="base_link">
    <inertial>
      <origin rpy="0 0 0" xyz="-0.00124874653232387 0.000246598785695634 -0.111598785207968"/>
      <mass value="1.64221424158838"/>
      <inertia ixx="0.0504230367553516" ixy="9.48207899309714E-06" ixz="0.000402652939677059" iyy="0.0425230890142074" iyz="3.19033530756586E-05" izz="0.0360972564220646"/>
    </inertial>
    <visual>
      <origin rpy="0 0 0" xyz="0 0 0"/>
      <geometry>
        <mesh filename="package://walker_description/meshes/base_link.STL"/>
      </geometry>
      <material name="">
        <color rgba="1 1 1 1"/>
      </material>
    </visual>
    <collision>
      <origin rpy="0 0 0" xyz="0 0 -0.115"/>
      <geometry>
        <box size="0.260 0.340 0.440"/>
      </geometry>
    </collision>
  </link>
  <gazebo reference="base_link">
    <!-- <selfCollide>true</selfCollide>-->
  </gazebo>
  <!--<xacro:include filename="$(find walker_description)/urdf/common/env.xacro" />-->
  <link name="head_l1">
    <inertial>
      <origin rpy="0 0 0" xyz="-0.00101176466106917 2.14927259107045E-05 2.40864327796242E-05"/>
      <mass value="0.03301938209839"/>
      <inertia ixx="4.47378645859374E-05" ixy="2.81915971226672E-10" ixz="-2.7372190471876E-10" iyy="4.50204226321243E-05" iyz="9.47033251934058E-08" izz="8.09468687396382E-05"/>
    </inertial>
    <visual>
      <origin rpy="0 0 0" xyz="0 0 0"/>
      <geometry>
        <mesh filename="package://walker_description/meshes/head_l1.STL"/>
      </geometry>
      <material name="">
        <color rgba="0.752941176470588 0.752941176470588 0.752941176470588 1"/>
      </material>
    </visual>
    <!--<collision>
      <origin xyz="0 0 0" rpy="0 0 0" />
      <geometry>
        <sphere radius="0.060"/>
      </geometry>
    </collision>-->
  </link>
  <gazebo reference="head_l1">
    <!-- <selfCollide>true</selfCollide>-->
  </gazebo>
  <joint name="head_j1" type="revolute">
    <origin rpy="0.0016575 -7.7846E-07 -1.2903E-09" xyz="0 -0.00016327 0.098503"/>
    <parent link="base_link"/>
    <child link="head_l1"/>
    <axis xyz="0 0 1"/>
    <limit effort="10" lower="-1.5708" upper="1.5708" velocity="1.8"/>
    <dynamics damping="5" friction="0.0"/>
  </joint>
  <gazebo reference="head_j1">
    <implicitSpringDamper>true</implicitSpringDamper>
  </gazebo>
  <link name="head_l2">
    <inertial>
      <origin rpy="0 0 0" xyz="-0.00101176466106917 2.40864327796242E-05 -2.14927259107045E-05"/>
      <mass value="0.03301938209839"/>
      <inertia ixx="4.47378645859374E-05" ixy="-2.7372190471876E-10" ixz="-2.81915971226672E-10" iyy="8.09468687396382E-05" iyz="-9.47033251934058E-08" izz="4.50204226321243E-05"/>
    </inertial>
    <visual>
      <origin rpy="0 0 0" xyz="0 0 0"/>
      <geometry>
        <mesh filename="package://walker_description/meshes/head_l2.STL"/>
      </geometry>
      <material name="">
        <color rgba="0.752941176470588 0.752941176470588 0.752941176470588 1"/>
      </material>
    </visual>
    <!--<collision>
      <origin xyz="0 0 0" rpy="0 0 0" />
      <geometry>
        <sphere radius="0.060"/>
      </geometry>
    </collision>-->
  </link>
  <gazebo reference="head_l2">
    <!-- <selfCollide>true</selfCollide>-->
  </gazebo>
  <joint name="head_j2" type="revolute">
    <origin rpy="1.5708 0 0" xyz="0 0 0"/>
    <parent link="head_l1"/>
    <child link="head_l2"/>
    <axis xyz="0 0 -1"/>
    <limit effort="10" lower="-0.2618" upper="0.2618" velocity="1.8"/>
    <dynamics damping="5" friction="0.0"/>
  </joint>
  <gazebo reference="head_j2">
    <implicitSpringDamper>true</implicitSpringDamper>
  </gazebo>
  <link name="head_l3">
    <inertial>
      <origin rpy="0 0 0" xyz="3.54592869765136E-05 0.042862147376731 -0.0791185735185245"/>
      <mass value="1.20773190668416"/>
      <inertia ixx="0.0074510060066946" ixy="-8.62633515792341E-07" ixz="4.68776412376015E-06" iyy="0.00893488331919255" iyz="0.000394324512736982" izz="0.0106759110882988"/>
    </inertial>
    <visual>
      <origin rpy="0 0 0" xyz="0 0 0"/>
      <geometry>
        <mesh filename="package://walker_description/meshes/head_l3.STL"/>
      </geometry>
      <material name="">
        <color rgba="0.752941176470588 0.752941176470588 0.752941176470588 1"/>
      </material>
    </visual>
    <collision>
      <origin rpy="0 0 0" xyz="0 0.050 -0.095"/>
      <geometry>
        <box size="0.240 0.200 0.180"/>
      </geometry>
    </collision>
  </link>
  <gazebo reference="head_l3">
    <!-- <selfCollide>true</selfCollide>-->
  </gazebo>
  <joint name="head_j3" type="fixed">
    <origin rpy="7.2818E-07 1.5708 0" xyz="0.084415 0.093313 0.00013289"/>
    <parent link="head_l2"/>
    <child link="head_l3"/>
    <axis xyz="0 0 0"/>
  </joint>
  <gazebo reference="head_j3">
    <implicitSpringDamper>true</implicitSpringDamper>
  </gazebo>
  <transmission name="head_tran1">
    <type>transmission_interface/SimpleTransmission</type>
    <joint name="head_j1">
      <hardwareInterface>PositionJointInterface</hardwareInterface>
    </joint>
    <actuator name="head_motor1">
      <hardwareInterface>PositionJointInterface</hardwareInterface>
      <mechanicalReduction>1</mechanicalReduction>
    </actuator>
  </transmission>
  <transmission name="head_tran2">
    <type>transmission_interface/SimpleTransmission</type>
    <joint name="head_j2">
      <hardwareInterface>PositionJointInterface</hardwareInterface>
    </joint>
    <actuator name="head_motor2">
      <hardwareInterface>PositionJointInterface</hardwareInterface>
      <mechanicalReduction>1</mechanicalReduction>
    </actuator>
  </transmission>
  <link name="left_limb_l1">
    <inertial>
      <origin rpy="0 0 0" xyz="-0.00723118478663554 -0.000176692959083069 -0.0361510146492087"/>
      <mass value="0.09064256447825"/>
      <inertia ixx="0.000311546571609671" ixy="1.46233470421987E-07" ixz="9.38915560600783E-06" iyy="0.000215270106429758" iyz="-1.74887531239783E-07" izz="0.000396323890766572"/>
    </inertial>
    <visual>
      <origin rpy="0 0 0" xyz="0 0 0"/>
      <geometry>
        <mesh filename="package://walker_description/meshes/left_limb_l1.STL"/>
      </geometry>
      <material name="">
        <color rgba="0.752941176470588 0.752941176470588 0.752941176470588 1"/>
      </material>
    </visual>
    <!--<collision>
      <origin xyz="0 0 0" rpy="0 0 0" />
      <geometry>
        <sphere radius="0.090"/>
      </geometry>
    </collision>-->
  </link>
  <gazebo reference="left_limb_l1">
    <!-- <selfCollide>true</selfCollide>-->
  </gazebo>
  <joint name="left_limb_j1" type="revolute">
    <origin rpy="0 1.309 1.5708" xyz="0 0.23066 0"/>
    <!--rpy="-1.931E-07 1.3073 1.5708" xyz="0 0.24 0.018386"-->
    <parent link="base_link"/>
    <child link="left_limb_l1"/>
    <axis xyz="0 0 -1"/>
    <limit effort="30.0" lower="-0.7854" upper="3.1416" velocity="2.0944"/>
    <dynamics damping="15" friction="0.0"/>
  </joint>
  <gazebo reference="left_limb_j1">
    <implicitSpringDamper>true</implicitSpringDamper>
  </gazebo>
  <link name="left_limb_l2">
    <inertial>
      <origin rpy="0 0 0" xyz="-0.000955809738594438 -0.0269333403261616 -0.000117719319276288"/>
      <mass value="0.111652182905858"/>
      <inertia ixx="0.000356827361185567" ixy="-1.12533439596274E-06" ixz="-2.65449628458759E-07" iyy="0.000282975717348096" iyz="3.29216684248187E-07" izz="0.000383024214388443"/>
    </inertial>
    <visual>
      <origin rpy="0 0 0" xyz="0 0 0"/>
      <geometry>
        <mesh filename="package://walker_description/meshes/left_limb_l2.STL"/>
      </geometry>
      <material name="">
        <color rgba="0.752941176470588 0.752941176470588 0.752941176470588 1"/>
      </material>
    </visual>
    <collision>
      <origin rpy="-1.5708 0 0" xyz="0 -0.100 0"/>
      <geometry>
        <cylinder length="0.310" radius="0.050"/>
      </geometry>
    </collision>
  </link>
  <gazebo reference="left_limb_l2">
    <!-- <selfCollide>true</selfCollide>-->
  </gazebo>
  <joint name="left_limb_j2" type="revolute">
    <origin rpy="-1.5708 1.5708 0" xyz="0 0 0"/>
    <parent link="left_limb_l1"/>
    <child link="left_limb_l2"/>
    <axis xyz="0 0 1"/>
    <limit effort="25.0" lower="-1.9199" upper="0" velocity="3.1416"/>
    <dynamics damping="8.0" friction="0.0"/>
  </joint>
  <gazebo reference="left_limb_j2">
    <implicitSpringDamper>true</implicitSpringDamper>
  </gazebo>
  <link name="left_limb_l3">
    <inertial>
      <origin rpy="0 0 0" xyz="0.00627269966291399 0.000194319566014622 -0.0621535107459378"/>
      <mass value="0.135126939485109"/>
      <inertia ixx="0.000578159440804691" ixy="-1.08669345396027E-06" ixz="-2.63187856402938E-05" iyy="0.000555746273124769" iyz="2.42748185068102E-07" izz="0.000446781938976979"/>
    </inertial>
    <visual>
      <origin rpy="0 0 0" xyz="0 0 0"/>
      <geometry>
        <mesh filename="package://walker_description/meshes/left_limb_l3.STL"/>
      </geometry>
      <material name="">
        <color rgba="0.752941176470588 0.752941176470588 0.752941176470588 1"/>
      </material>
    </visual>
    <!--<collision>
      <origin xyz="0.000 0 -0.050" rpy="0 0 0" />
      <geometry>
        <cylinder length="0.150" radius="0.050"/>
      </geometry>
    </collision>-->
  </link>
  <gazebo reference="left_limb_l3">
    <!-- <selfCollide>true</selfCollide>-->
  </gazebo>
  <joint name="left_limb_j3" type="revolute">
    <origin rpy="1.5708 6.1653E-11 -2.7756E-17" xyz="0 -0.230 0"/>
    <!--xyz="-0.00064368 -0.2285 0"-->
    <parent link="left_limb_l2"/>
    <child link="left_limb_l3"/>
    <axis xyz="0 0 1"/>
    <limit effort="15.0" lower="-1.9199" upper="1.9199" velocity="3.1416"/>
    <dynamics damping="5.0" friction="0.0"/>
  </joint>
  <gazebo reference="left_limb_j3">
    <implicitSpringDamper>true</implicitSpringDamper>
  </gazebo>
  <link name="left_limb_l4">
    <inertial>
      <origin rpy="0 0 0" xyz="0.0187474263134242 -0.0269365900000591 -0.000697445026925037"/>
      <mass value="0.11154629806895"/>
      <inertia ixx="0.000288454207747691" ixy="3.82699694956323E-05" ixz="-1.38775292413934E-06" iyy="0.000238329463729007" iyz="1.48262510934948E-06" izz="0.000322652845197087"/>
    </inertial>
    <visual>
      <origin rpy="0 0 0" xyz="0 0 0"/>
      <geometry>
        <mesh filename="package://walker_description/meshes/left_limb_l4.STL"/>
      </geometry>
      <material name="">
        <color rgba="0.752941176470588 0.752941176470588 0.752941176470588 1"/>
      </material>
    </visual>
    <!--<collision>
      <origin xyz="0.010 -0.020 0" rpy="1.5708 0 0" />
      <geometry>
        <cylinder length="0.150" radius="0.065"/>
      </geometry>
    </collision>-->
  </link>
  <gazebo reference="left_limb_l4">
    <!-- <selfCollide>true</selfCollide>-->
  </gazebo>
  <joint name="left_limb_j4" type="revolute">
    <origin rpy="-1.5708 0 3.1416" xyz="0.025422 0 0"/>
    <!--rpy="-1.5708 -0.046339 3.1416"-->
    <parent link="left_limb_l3"/>
    <child link="left_limb_l4"/>
    <axis xyz="0 0 1"/>
    <limit effort="15.0" lower="-2.2689" upper="0" velocity="3.1416"/>
    <dynamics damping="5.0" friction="0.0"/>
  </joint>
  <gazebo reference="left_limb_j4">
    <implicitSpringDamper>true</implicitSpringDamper>
  </gazebo>
  <link name="left_limb_l5">
    <inertial>
      <origin rpy="0 0 0" xyz="0.000547047098985842 -0.000122519646228891 -0.0604686375411661"/>
      <mass value="0.102338558748505"/>
      <inertia ixx="0.000317253893378568" ixy="9.52809865361354E-09" ixz="1.23465056753508E-06" iyy="0.000310424822694819" iyz="1.308971178147E-06" izz="0.000201818691915583"/>
    </inertial>
    <visual>
      <origin rpy="0 0 0" xyz="0 0 0"/>
      <geometry>
        <mesh filename="package://walker_description/meshes/left_limb_l5.STL"/>
      </geometry>
      <material name="">
        <color rgba="0.752941176470588 0.752941176470588 0.752941176470588 1"/>
      </material>
    </visual>
    <collision>
      <origin rpy="0 0 0" xyz="0 0 -0.080"/>
      <geometry>
        <cylinder length="0.180" radius="0.050"/>
      </geometry>
    </collision>
  </link>
  <gazebo reference="left_limb_l5">
    <!-- <selfCollide>true</selfCollide>-->
  </gazebo>
  <joint name="left_limb_j5" type="revolute">
    <origin rpy="-1.5708 -1.5708 -3.1416" xyz="0.024818 -0.22485 0"/>
    <!--xyz="0.024818 -0.22241 0"-->
    <parent link="left_limb_l4"/>
    <child link="left_limb_l5"/>
    <axis xyz="0 0 1"/>
    <limit effort="10.0" lower="-2.3562" upper="2.3562" velocity="3.1416"/>
    <dynamics damping="5.0" friction="0.5"/>
  </joint>
  <gazebo reference="left_limb_j5">
    <implicitSpringDamper>true</implicitSpringDamper>
  </gazebo>
  <link name="left_limb_l6">
    <inertial>
      <origin rpy="0 0 0" xyz="0.0125425664529848 0.000622049029732841 0.000522268941341331"/>
      <mass value="0.0224426274363224"/>
      <inertia ixx="2.99031109754486E-05" ixy="1.80107466242641E-07" ixz="1.2083547861949E-08" iyy="1.83549287965366E-05" iyz="-3.56041365932581E-09" izz="1.79186235677719E-05"/>
    </inertial>
    <visual>
      <origin rpy="0 0 0" xyz="0 0 0"/>
      <geometry>
        <mesh filename="package://walker_description/meshes/left_limb_l6.STL"/>
      </geometry>
      <material name="">
        <color rgba="0.752941176470588 0.752941176470588 0.752941176470588 1"/>
      </material>
    </visual>
    <!--<collision>
      <origin xyz="0 0 0" rpy="0 0 0" />
      <geometry>
        <sphere radius="0.045"/>
      </geometry>
    </collision>-->
  </link>
  <gazebo reference="left_limb_l6">
    <!-- <selfCollide>true</selfCollide>-->
  </gazebo>
  <joint name="left_limb_j6" type="revolute">
    <origin rpy="1.5708 -1.5708 0" xyz="0 0 0"/>
    <parent link="left_limb_l5"/>
    <child link="left_limb_l6"/>
    <axis xyz="0 0 -1"/>
    <limit effort="10.0" lower="-0.4363" upper="0.4363" velocity="3.1416"/>
    <dynamics damping="5.0" friction="0.5"/>
  </joint>
  <gazebo reference="left_limb_j6">
    <implicitSpringDamper>true</implicitSpringDamper>
  </gazebo>
  <link name="left_limb_l7">
    <inertial>
      <origin rpy="0 0 0" xyz="0.0125425664529848 0.000522268941341331 -0.000622049029732841"/>
      <mass value="0.0224426274363224"/>
      <inertia ixx="2.99031109754486E-05" ixy="1.2083547861949E-08" ixz="-1.80107466242641E-07" iyy="1.79186235677719E-05" iyz="3.56041365932573E-09" izz="1.83549287965366E-05"/>
    </inertial>
    <visual>
      <origin rpy="0 0 0" xyz="0 0 0"/>
      <geometry>
        <mesh filename="package://walker_description/meshes/left_limb_l7.STL"/>
      </geometry>
      <material name="">
        <color rgba="0.752941176470588 0.752941176470588 0.752941176470588 1"/>
      </material>
    </visual>
    <!--<collision>
      <origin xyz="0 0 0" rpy="0 0 0" />
      <geometry>
        <sphere radius="0.045"/>
      </geometry>
    </collision>-->
  </link>
  <gazebo reference="left_limb_l7">
    <!-- <selfCollide>true</selfCollide>-->
  </gazebo>
  <joint name="left_limb_j7" type="revolute">
    <origin rpy="-1.5708 3.0389E-17 6.4236E-24" xyz="0 0 0"/>
    <!--rpy="1.5708 3.0389E-17 6.4236E-24"-->
    <parent link="left_limb_l6"/>
    <child link="left_limb_l7"/>
    <axis xyz="0 0 -1"/>
    <limit effort="10.0" lower="-0.4363" upper="0.4363" velocity="3.1416"/>
    <dynamics damping="5.0" friction="0.5"/>
  </joint>
  <gazebo reference="left_limb_j7">
    <implicitSpringDamper>true</implicitSpringDamper>
  </gazebo>
  <transmission name="left_limb_tran1">
    <type>transmission_interface/SimpleTransmission</type>
    <joint name="left_limb_j1">
      <hardwareInterface>PositionJointInterface</hardwareInterface>
    </joint>
    <actuator name="left_limb_motor1">
      <hardwareInterface>PositionJointInterface</hardwareInterface>
      <mechanicalReduction>1</mechanicalReduction>
    </actuator>
  </transmission>
  <transmission name="left_limb_tran2">
    <type>transmission_interface/SimpleTransmission</type>
    <joint name="left_limb_j2">
      <hardwareInterface>PositionJointInterface</hardwareInterface>
    </joint>
    <actuator name="left_limb_motor2">
      <hardwareInterface>PositionJointInterface</hardwareInterface>
      <mechanicalReduction>1</mechanicalReduction>
    </actuator>
  </transmission>
  <transmission name="left_limb_tran3">
    <type>transmission_interface/SimpleTransmission</type>
    <joint name="left_limb_j3">
      <hardwareInterface>PositionJointInterface</hardwareInterface>
    </joint>
    <actuator name="left_limb_motor3">
      <hardwareInterface>PositionJointInterface</hardwareInterface>
      <mechanicalReduction>1</mechanicalReduction>
    </actuator>
  </transmission>
  <transmission name="left_limb_tran4">
    <type>transmission_interface/SimpleTransmission</type>
    <joint name="left_limb_j4">
      <hardwareInterface>PositionJointInterface</hardwareInterface>
    </joint>
    <actuator name="left_limb_motor4">
      <hardwareInterface>PositionJointInterface</hardwareInterface>
      <mechanicalReduction>1</mechanicalReduction>
    </actuator>
  </transmission>
  <transmission name="left_limb_tran5">
    <type>transmission_interface/SimpleTransmission</type>
    <joint name="left_limb_j5">
      <hardwareInterface>PositionJointInterface</hardwareInterface>
    </joint>
    <actuator name="left_limb_motor5">
      <hardwareInterface>PositionJointInterface</hardwareInterface>
      <mechanicalReduction>1</mechanicalReduction>
    </actuator>
  </transmission>
  <transmission name="left_limb_tran6">
    <type>transmission_interface/SimpleTransmission</type>
    <joint name="left_limb_j6">
      <hardwareInterface>PositionJointInterface</hardwareInterface>
    </joint>
    <actuator name="left_limb_motor6">
      <hardwareInterface>PositionJointInterface</hardwareInterface>
      <mechanicalReduction>1</mechanicalReduction>
    </actuator>
  </transmission>
  <transmission name="left_limb_tran7">
    <type>transmission_interface/SimpleTransmission</type>
    <joint name="left_limb_j7">
      <hardwareInterface>PositionJointInterface</hardwareInterface>
    </joint>
    <actuator name="left_limb_motor7">
      <hardwareInterface>PositionJointInterface</hardwareInterface>
      <mechanicalReduction>1</mechanicalReduction>
    </actuator>
  </transmission>
  <link name="right_limb_l1">
    <inertial>
      <origin rpy="0 0 0" xyz="-0.00722075380474052 0.00018206355096656 -0.0361420965458128"/>
      <mass value="0.0906357127023235"/>
      <inertia ixx="0.000311522358740572" ixy="9.35574756778802E-08" ixz="9.36994646655713E-06" iyy="0.000215286397239846" iyz="1.95199653306613E-07" izz="0.000396295467948814"/>
    </inertial>
    <visual>
      <origin rpy="0 0 0" xyz="0 0 0"/>
      <geometry>
        <mesh filename="package://walker_description/meshes/right_limb_l1.STL"/>
      </geometry>
      <material name="">
        <color rgba="0.752941176470588 0.752941176470588 0.752941176470588 1"/>
      </material>
    </visual>
    <!--<collision>
      <origin xyz="0 0 0" rpy="0 0 0" />
      <geometry>
        <sphere radius="0.090"/>
      </geometry>
    </collision>-->
  </link>
  <gazebo reference="right_limb_l1">
    <!-- <selfCollide>true</selfCollide>-->
  </gazebo>
  <joint name="right_limb_j1" type="revolute">
    <origin rpy="-1.9576E-06 1.309 -1.5708" xyz="0 -0.23 0"/>
    <!--xyz="0 -0.24 0.0163"-->
    <parent link="base_link"/>
    <child link="right_limb_l1"/>
    <axis xyz="0 0 -1"/>
    <limit effort="30.0" lower="-3.1416" upper="0.7854" velocity="2.0944"/>
    <dynamics damping="15" friction="0.0"/>
  </joint>
  <gazebo reference="right_limb_j1">
    <implicitSpringDamper>true</implicitSpringDamper>
  </gazebo>
  <link name="right_limb_l2">
    <inertial>
      <origin rpy="0 0 0" xyz="-0.00196280070849958 0.0273168501674689 -0.000134287637530983"/>
      <mass value="0.113461395789569"/>
      <inertia ixx="0.000358148474769472" ixy="4.04459296835336E-06" ixz="-1.32587419890427E-07" iyy="0.000288726351260568" iyz="-2.60810750383463E-07" izz="0.000390106430816898"/>
    </inertial>
    <visual>
      <origin rpy="0 0 0" xyz="0 0 0"/>
      <geometry>
        <mesh filename="package://walker_description/meshes/right_limb_l2.STL"/>
      </geometry>
      <material name="">
        <color rgba="0.752941176470588 0.752941176470588 0.752941176470588 1"/>
      </material>
    </visual>
    <collision>
      <origin rpy="-1.5708 0 0" xyz="0 0.100 0"/>
      <geometry>
        <cylinder length="0.310" radius="0.050"/>
      </geometry>
    </collision>
  </link>
  <gazebo reference="right_limb_l2">
    <!-- <selfCollide>true</selfCollide>-->
  </gazebo>
  <joint name="right_limb_j2" type="revolute">
    <origin rpy="1.5708 1.5708 0" xyz="0 0 0"/>
    <!--rpy="2.5133 1.5708 0.94251"-->
    <parent link="right_limb_l1"/>
    <child link="right_limb_l2"/>
    <axis xyz="0 0 -1"/>
    <limit effort="25.0" lower="-1.9199" upper="0" velocity="3.1416"/>
    <dynamics damping="8.0" friction="0.0"/>
  </joint>
  <gazebo reference="right_limb_j2">
    <implicitSpringDamper>true</implicitSpringDamper>
  </gazebo>
  <link name="right_limb_l3">
    <inertial>
      <origin rpy="0 0 0" xyz="0.00629656239509124 -0.000210202146791738 -0.0621806056819392"/>
      <mass value="0.135195223417304"/>
      <inertia ixx="0.000578598259089345" ixy="1.06936365158182E-06" ixz="-2.64856345206634E-05" iyy="0.00055597686018737" iyz="-3.95057844818631E-07" izz="0.000447021332772512"/>
    </inertial>
    <visual>
      <origin rpy="0 0 0" xyz="0 0 0"/>
      <geometry>
        <mesh filename="package://walker_description/meshes/right_limb_l3.STL"/>
      </geometry>
      <material name="">
        <color rgba="0.752941176470588 0.752941176470588 0.752941176470588 1"/>
      </material>
    </visual>
    <!--<collision>
      <origin xyz="0.000 0 -0.050" rpy="0 0 0" />
      <geometry>
        <cylinder length="0.150" radius="0.050"/>
      </geometry>
    </collision>-->
  </link>
  <gazebo reference="right_limb_l3">
    <!-- <selfCollide>true</selfCollide>-->
  </gazebo>
  <joint name="right_limb_j3" type="revolute">
    <origin rpy="-1.5708 -5.382E-07 1.8518E-13" xyz="-0.00064368 0.22946 0"/>
    <parent link="right_limb_l2"/>
    <child link="right_limb_l3"/>
    <axis xyz="0 0 1"/>
    <limit effort="15.0" lower="-1.9199" upper="1.9199" velocity="3.1416"/>
    <dynamics damping="5.0" friction="0.0"/>
  </joint>
  <gazebo reference="right_limb_j3">
    <implicitSpringDamper>true</implicitSpringDamper>
  </gazebo>
  <link name="right_limb_l4">
    <inertial>
      <origin rpy="0 0 0" xyz="0.0187332468499471 0.0270289413426348 -0.000700111734367903"/>
      <mass value="0.111555587464306"/>
      <inertia ixx="0.000288414802228566" ixy="-3.8255971416539E-05" ixz="-1.37491897701909E-06" iyy="0.000238322279447384" iyz="-1.45890833294397E-06" izz="0.00032269764599304"/>
    </inertial>
    <visual>
      <origin rpy="0 0 0" xyz="0 0 0"/>
      <geometry>
        <mesh filename="package://walker_description/meshes/right_limb_l4.STL"/>
      </geometry>
      <material name="">
        <color rgba="0.752941176470588 0.752941176470588 0.752941176470588 1"/>
      </material>
    </visual>
    <!--<collision>
      <origin xyz="0.010 0.020 0" rpy="1.5708 0 0" />
      <geometry>
        <cylinder length="0.150" radius="0.065"/>
      </geometry>
    </collision>-->
  </link>
  <gazebo reference="right_limb_l4">
    <!-- <selfCollide>true</selfCollide>-->
  </gazebo>
  <joint name="right_limb_j4" type="revolute">
    <origin rpy="1.5708 0 -3.1416" xyz="0.0248 0 0"/>
    <!--rpy="1.5708 -0.050009 -3.1416" xyz="0.02546 0 0"-->
    <parent link="right_limb_l3"/>
    <child link="right_limb_l4"/>
    <axis xyz="0 0 -1"/>
    <limit effort="15.0" lower="-2.2689" upper="0" velocity="3.1416"/>
    <dynamics damping="5.0" friction="0.0"/>
  </joint>
  <gazebo reference="right_limb_j4">
    <implicitSpringDamper>true</implicitSpringDamper>
  </gazebo>
  <link name="right_limb_l5">
    <inertial>
      <origin rpy="0 0 0" xyz="-0.000596823513585643 0.000121710879949499 -0.0604708516266729"/>
      <mass value="0.102332990879977"/>
      <inertia ixx="0.000317212358011218" ixy="8.88268591236389E-08" ixz="-1.43322638083369E-06" iyy="0.000310459779022516" iyz="-1.31927102955738E-06" izz="0.00020181632910904"/>
    </inertial>
    <visual>
      <origin rpy="0 0 0" xyz="0 0 0"/>
      <geometry>
        <mesh filename="package://walker_description/meshes/right_limb_l5.STL"/>
      </geometry>
      <material name="">
        <color rgba="0.752941176470588 0.752941176470588 0.752941176470588 1"/>
      </material>
    </visual>
    <collision>
      <origin rpy="0 0 0" xyz="0 0 -0.080"/>
      <geometry>
        <cylinder length="0.180" radius="0.050"/>
      </geometry>
    </collision>
  </link>
  <gazebo reference="right_limb_l5">
    <!-- <selfCollide>true</selfCollide>-->
  </gazebo>
  <joint name="right_limb_j5" type="revolute">
    <origin rpy="0 -1.5708 -1.5708" xyz="0.0248 0.22485 0"/>
    <!--rpy="-0.26632 -1.5708 -1.3045" xyz="0.024799 0.20964 0"-->
    <parent link="right_limb_l4"/>
    <child link="right_limb_l5"/>
    <axis xyz="0 0 1"/>
    <limit effort="10.0" lower="-2.3562" upper="2.3562" velocity="3.1416"/>
    <dynamics damping="5.0" friction="0.5"/>
  </joint>
  <gazebo reference="right_limb_j5">
    <implicitSpringDamper>true</implicitSpringDamper>
  </gazebo>
  <link name="right_limb_l6">
    <inertial>
      <origin rpy="0 0 0" xyz="0.012844513924211 0.000377301016693532 -0.000161615308549884"/>
      <mass value="0.0224407079927881"/>
      <inertia ixx="2.98997054662712E-05" ixy="-1.80995710653271E-07" ixz="1.11151156522585E-08" iyy="1.83543369800587E-05" iyz="4.0198944319711E-09" izz="1.79177399902661E-05"/>
    </inertial>
    <visual>
      <origin rpy="0 0 0" xyz="0 0 0"/>
      <geometry>
        <mesh filename="package://walker_description/meshes/right_limb_l6.STL"/>
      </geometry>
      <material name="">
        <color rgba="0.752941176470588 0.752941176470588 0.752941176470588 1"/>
      </material>
    </visual>
    <!--<collision>
      <origin xyz="0 0 0" rpy="0 0 0" />
      <geometry>
        <sphere radius="0.045"/>
      </geometry>
    </collision>-->
  </link>
  <gazebo reference="right_limb_l6">
    <!-- <selfCollide>true</selfCollide>-->
  </gazebo>
  <joint name="right_limb_j6" type="revolute">
    <origin rpy="-1.5708 -1.5708 3.1416" xyz="0 0 0"/>
    <parent link="right_limb_l5"/>
    <child link="right_limb_l6"/>
    <axis xyz="0 0 1"/>
    <limit effort="10.0" lower="-0.4363" upper="0.4363" velocity="3.1416"/>
    <dynamics damping="5.0" friction="0.5"/>
  </joint>
  <gazebo reference="right_limb_j6">
    <implicitSpringDamper>true</implicitSpringDamper>
  </gazebo>
  <link name="right_limb_l7">
    <inertial>
      <origin rpy="0 0 0" xyz="0.0128445139242118 -0.000161615367551576 -0.000377300991420526"/>
      <mass value="0.0224407079927881"/>
      <inertia ixx="2.98997054662712E-05" ixy="1.11151439560756E-08" ixz="1.80995708915103E-07" iyy="1.79177399890089E-05" iyz="-4.01982615763892E-09" izz="1.83543369813159E-05"/>
    </inertial>
    <visual>
      <origin rpy="0 0 0" xyz="0 0 0"/>
      <geometry>
        <mesh filename="package://walker_description/meshes/right_limb_l7.STL"/>
      </geometry>
      <material name="">
        <color rgba="0.752941176470588 0.752941176470588 0.752941176470588 1"/>
      </material>
    </visual>
    <!--<collision>
      <origin xyz="0 0 0" rpy="0 0 0" />
      <geometry>
        <sphere radius="0.045"/>
      </geometry>
    </collision>-->
  </link>
  <gazebo reference="right_limb_l7">
    <!-- <selfCollide>true</selfCollide>-->
  </gazebo>
  <joint name="right_limb_j7" type="revolute">
    <origin rpy="1.5708 -5.9686E-17 -1.3235E-23" xyz="0 0 0"/>
    <parent link="right_limb_l6"/>
    <child link="right_limb_l7"/>
    <axis xyz="0 0 1"/>
    <limit effort="10.0" lower="-0.4363" upper="0.4363" velocity="3.1416"/>
    <dynamics damping="5.0" friction="0.5"/>
  </joint>
  <gazebo reference="right_limb_j7">
    <implicitSpringDamper>true</implicitSpringDamper>
  </gazebo>
  <transmission name="right_limb_tran1">
    <type>transmission_interface/SimpleTransmission</type>
    <joint name="right_limb_j1">
      <hardwareInterface>PositionJointInterface</hardwareInterface>
    </joint>
    <actuator name="right_limb_motor1">
      <hardwareInterface>PositionJointInterface</hardwareInterface>
      <mechanicalReduction>1</mechanicalReduction>
    </actuator>
  </transmission>
  <transmission name="right_limb_tran2">
    <type>transmission_interface/SimpleTransmission</type>
    <joint name="right_limb_j2">
      <hardwareInterface>PositionJointInterface</hardwareInterface>
    </joint>
    <actuator name="right_limb_motor2">
      <hardwareInterface>PositionJointInterface</hardwareInterface>
      <mechanicalReduction>1</mechanicalReduction>
    </actuator>
  </transmission>
  <transmission name="right_limb_tran3">
    <type>transmission_interface/SimpleTransmission</type>
    <joint name="right_limb_j3">
      <hardwareInterface>PositionJointInterface</hardwareInterface>
    </joint>
    <actuator name="right_limb_motor3">
      <hardwareInterface>PositionJointInterface</hardwareInterface>
      <mechanicalReduction>1</mechanicalReduction>
    </actuator>
  </transmission>
  <transmission name="right_limb_tran4">
    <type>transmission_interface/SimpleTransmission</type>
    <joint name="right_limb_j4">
      <hardwareInterface>PositionJointInterface</hardwareInterface>
    </joint>
    <actuator name="right_limb_motor4">
      <hardwareInterface>PositionJointInterface</hardwareInterface>
      <mechanicalReduction>1</mechanicalReduction>
    </actuator>
  </transmission>
  <transmission name="right_limb_tran5">
    <type>transmission_interface/SimpleTransmission</type>
    <joint name="right_limb_j5">
      <hardwareInterface>PositionJointInterface</hardwareInterface>
    </joint>
    <actuator name="right_limb_motor5">
      <hardwareInterface>PositionJointInterface</hardwareInterface>
      <mechanicalReduction>1</mechanicalReduction>
    </actuator>
  </transmission>
  <transmission name="right_limb_tran6">
    <type>transmission_interface/SimpleTransmission</type>
    <joint name="right_limb_j6">
      <hardwareInterface>PositionJointInterface</hardwareInterface>
    </joint>
    <actuator name="right_limb_motor6">
      <hardwareInterface>PositionJointInterface</hardwareInterface>
      <mechanicalReduction>1</mechanicalReduction>
    </actuator>
  </transmission>
  <transmission name="right_limb_tran7">
    <type>transmission_interface/SimpleTransmission</type>
    <joint name="right_limb_j7">
      <hardwareInterface>PositionJointInterface</hardwareInterface>
    </joint>
    <actuator name="right_limb_motor7">
      <hardwareInterface>PositionJointInterface</hardwareInterface>
      <mechanicalReduction>1</mechanicalReduction>
    </actuator>
  </transmission>
  --&gt;

    
  <link name="left_palm_link">
    <inertial>
      <origin rpy="0 0 0" xyz="0.0144809215118954 -0.0132347085538364 0.022306335464008"/>
      <mass value="0.0852752510078387"/>
      <inertia ixx="0.000154775131402232" ixy="1.85109602266807E-05" ixz="7.47252049170957E-06" iyy="0.000107981762301999" iyz="-1.08345230717271E-06" izz="0.000125562926987643"/>
    </inertial>
    <visual>
      <origin rpy="0 0 0" xyz="0 0 0"/>
      <geometry>
        <mesh filename="package://walker_description/meshes/left_palm_link.STL"/>
      </geometry>
      <material name="">
        <color rgba="0.752941176470588 0.752941176470588 0.752941176470588 1"/>
      </material>
    </visual>
    <collision>
      <origin rpy="0 0 0" xyz="0.020 -0.005 0.020"/>
      <geometry>
        <box size="0.040 0.090 0.100"/>
      </geometry>
    </collision>
  </link>
  <gazebo reference="left_palm_link">
    <!-- <selfCollide>true</selfCollide>-->
    <material>Gazebo/White</material>
    <mu1>1000.0</mu1>
    <mu2>1000.0</mu2>
    <fdir1>0.0 0.0 1.0</fdir1>
    <kp>1e5</kp>
    <kd>1.0</kd>
  </gazebo>
  <joint name="left_palm_joint" type="fixed">
    <origin rpy="3.14159 0 -1.309" xyz="0.073849 0.0065547 0.01588"/>
    <!--py="3.14159 0 -1.35"xyz="0.073849 -0.0065547 -0.01588"-->
    <parent link="left_limb_l7"/>
    <child link="left_palm_link"/>
    <axis xyz="0 0 0"/>
  </joint>
  <gazebo reference="left_palm_joint">
    <implicitSpringDamper>true</implicitSpringDamper>
  </gazebo>
  <link name="left_thumb_l1">
    <inertial>
      <origin rpy="0 0 0" xyz="0.0109077935886571 0.000509912566104553 -0.00754109244201351"/>
      <mass value="0.00861402024435377"/>
      <inertia ixx="6.47370281406322E-07" ixy="-2.31312229115831E-08" ixz="-4.83971007188494E-09" iyy="1.90672646289156E-06" iyz="1.40014779445703E-09" izz="1.98821903169097E-06"/>
    </inertial>
    <visual>
      <origin rpy="0 0 0" xyz="0 0 0"/>
      <geometry>
        <mesh filename="package://walker_description/meshes/left_thumb_l1.STL"/>
      </geometry>
      <material name="">
        <color rgba="0.752941176470588 0.752941176470588 0.752941176470588 1"/>
      </material>
    </visual>
    <collision>
      <origin rpy="0 1.5708 0" xyz="0.008 0.002 -0.008"/>
      <geometry>
        <cylinder length="0.028" radius="0.012"/>
      </geometry>
    </collision>
  </link>
  <gazebo reference="left_thumb_l1">
    <!-- <selfCollide>true</selfCollide>-->
  </gazebo>
  <joint name="left_thumb_j1" type="revolute">
    <origin rpy="-0.21969 0.11307 -2.3458" xyz="-0.029569 -0.010189 0.047224"/>
    <parent link="left_palm_link"/>
    <child link="left_thumb_l1"/>
    <axis xyz="0 0 1"/>
    <limit effort="1.0" lower="0" upper="1.5708" velocity="10"/>
    <dynamics damping="0.01" friction="0.0"/>
  </joint>
  <gazebo reference="left_thumb_j1">
    <implicitSpringDamper>true</implicitSpringDamper>
  </gazebo>
  <link name="left_thumb_l2">
    <inertial>
      <origin rpy="0 0 0" xyz="-0.00326118817213394 -0.00670732804360867 0.00579509755504815"/>
      <mass value="0.00424320273530089"/>
      <inertia ixx="3.56339942071856E-07" ixy="-1.03305625527354E-07" ixz="-1.98675685150365E-08" iyy="2.76640278902837E-07" iyz="-2.89571665413786E-08" izz="4.20445500389883E-07"/>
    </inertial>
    <visual>
      <origin rpy="0 0 0" xyz="0 0 0"/>
      <geometry>
        <mesh filename="package://walker_description/meshes/left_thumb_l2.STL"/>
      </geometry>
      <material name="">
        <color rgba="0.752941176470588 0.752941176470588 0.752941176470588 1"/>
      </material>
    </visual>
    <collision>
      <origin rpy="0 1.5708 0.7854" xyz="-0.007 -0.009 0.007"/>
      <geometry>
        <cylinder length="0.025" radius="0.012"/>
      </geometry>
    </collision>
  </link>
  <gazebo reference="left_thumb_l2">
    <!-- <selfCollide>true</selfCollide>-->
    <material>Gazebo/White</material>
    <mu1>1000.0</mu1>
    <mu2>1000.0</mu2>
    <fdir1>0.0 0.0 1.0</fdir1>
    <kp>1e5</kp>
    <kd>1.0</kd>
  </gazebo>
  <joint name="left_thumb_j2" type="revolute">
    <origin rpy="-0.23401 -0.07871 2.3426" xyz="0.03655 0 -0.014552"/>
    <parent link="left_thumb_l1"/>
    <child link="left_thumb_l2"/>
    <axis xyz="0.078637 -0.23116 0.96973"/>
    <limit effort="1.0" lower="0" upper="1.5708" velocity="10"/>
    <dynamics damping="0.01" friction="0.0"/>
    <mimic joint="left_thumb_j1" multiplier="1.0" offset="0.0"/>
  </joint>
  <gazebo reference="left_thumb_j2">
    <implicitSpringDamper>true</implicitSpringDamper>
  </gazebo>
  <link name="left_index_l1">
    <inertial>
      <origin rpy="0 0 0" xyz="0.0150096995375729 -0.000417441681978437 -0.00617410792227591"/>
      <mass value="0.00596800864397499"/>
      <inertia ixx="3.61715487571409E-07" ixy="1.11394201694589E-08" ixz="-9.49522570972701E-09" iyy="1.352263185051E-06" iyz="3.77704526134077E-10" izz="1.37239697071942E-06"/>
    </inertial>
    <visual>
      <origin rpy="0 0 0" xyz="0 0 0"/>
      <geometry>
        <mesh filename="package://walker_description/meshes/left_index_l1.STL"/>
      </geometry>
      <material name="">
        <color rgba="0.752941176470588 0.752941176470588 0.752941176470588 1"/>
      </material>
    </visual>
    <collision>
      <origin rpy="0 1.5708 0" xyz="0.014 0 -0.005"/>
      <geometry>
        <cylinder length="0.034" radius="0.010"/>
      </geometry>
    </collision>
  </link>
  <gazebo reference="left_index_l1">
    <!-- <selfCollide>true</selfCollide>-->
  </gazebo>
  <joint name="left_index_j1" type="revolute">
    <origin rpy="0.007028 -0.014656 -1.7541" xyz="0.019862 -0.070838 0.061199"/>
    <parent link="left_palm_link"/>
    <child link="left_index_l1"/>
    <axis xyz="0 0 -1"/>
    <limit effort="1.0" lower="0" upper="1.5708" velocity="10"/>
    <dynamics damping="0.01" friction="0.0"/>
  </joint>
  <gazebo reference="left_index_j1">
    <implicitSpringDamper>true</implicitSpringDamper>
  </gazebo>
  <link name="left_index_l2">
    <inertial>
      <origin rpy="0 0 0" xyz="-0.00253991682124299 -0.00977023427268975 0.00611226603304443"/>
      <mass value="0.00445721097773791"/>
      <inertia ixx="5.54377117420834E-07" ixy="-8.29083645268593E-08" ixz="1.27238638879939E-09" iyy="2.07584978771715E-07" iyz="6.4186623927502E-09" izz="5.97533598597632E-07"/>
    </inertial>
    <visual>
      <origin rpy="0 0 0" xyz="0 0 0"/>
      <geometry>
        <mesh filename="package://walker_description/meshes/left_index_l2.STL"/>
      </geometry>
      <material name="">
        <color rgba="0.752941176470588 0.752941176470588 0.752941176470588 1"/>
      </material>
    </visual>
    <collision>
      <origin rpy="1.5708 0 -0.1745" xyz="-0.002 -0.014 0.007"/>
      <geometry>
        <cylinder length="0.032" radius="0.010"/>
      </geometry>
    </collision>
  </link>
  <gazebo reference="left_index_l2">
    <!-- <selfCollide>true</selfCollide>-->
    <material>Gazebo/White</material>
    <mu1>1000.0</mu1>
    <mu2>1000.0</mu2>
    <fdir1>0.0 0.0 1.0</fdir1>
    <kp>1e5</kp>
    <kd>1.0</kd>
  </gazebo>
  <joint name="left_index_j2" type="revolute">
    <origin rpy="0.015691 0.0042391 1.7541" xyz="0.038461 0 -0.012199"/>
    <parent link="left_index_l1"/>
    <child link="left_index_l2"/>
    <axis xyz="-0.004239 0.015691 -0.99987"/>
    <limit effort="1.0" lower="0" upper="1.5708" velocity="10"/>
    <dynamics damping="0.01" friction="0.0"/>
    <mimic joint="left_index_j1" multiplier="1.0" offset="0.0"/>
  </joint>
  <gazebo reference="left_index_j2">
    <implicitSpringDamper>true</implicitSpringDamper>
  </gazebo>
  <link name="left_middle_l1">
    <inertial>
      <origin rpy="0 0 0" xyz="0.0150066791389904 -0.000415057780457695 -0.00617388522006262"/>
      <mass value="0.0059679127929483"/>
      <inertia ixx="3.61683279235401E-07" ixy="1.10458760225662E-08" ixz="-9.52816793557932E-09" iyy="1.35225818715739E-06" iyz="4.31044880666154E-10" izz="1.37239159556213E-06"/>
    </inertial>
    <visual>
      <origin rpy="0 0 0" xyz="0 0 0"/>
      <geometry>
        <mesh filename="package://walker_description/meshes/left_middle_l1.STL"/>
      </geometry>
      <material name="">
        <color rgba="0.752941176470588 0.752941176470588 0.752941176470588 1"/>
      </material>
    </visual>
    <collision>
      <origin rpy="0 1.5708 0" xyz="0.014 0 -0.005"/>
      <geometry>
        <cylinder length="0.034" radius="0.010"/>
      </geometry>
    </collision>
  </link>
  <gazebo reference="left_middle_l1">
    <!-- <selfCollide>true</selfCollide>-->
  </gazebo>
  <joint name="left_middle_j1" type="revolute">
    <origin rpy="0.0068833 -0.014869 -1.7395" xyz="0.021755 -0.077461 0.037447"/>
    <parent link="left_palm_link"/>
    <child link="left_middle_l1"/>
    <axis xyz="0 0 -1"/>
    <limit effort="1.0" lower="0" upper="1.5708" velocity="10"/>
    <dynamics damping="0.01" friction="0.0"/>
  </joint>
  <gazebo reference="left_middle_j1">
    <implicitSpringDamper>true</implicitSpringDamper>
  </gazebo>
  <link name="left_middle_l2">
    <inertial>
      <origin rpy="0 0 0" xyz="-0.0022619297447487 -0.00982259010744915 0.00611526424902847"/>
      <mass value="0.004457212283002"/>
      <inertia ixx="5.58236463390729E-07" ixy="-7.2571176025331E-08" ixz="1.16573185460247E-09" iyy="1.98180605286849E-07" iyz="6.55275148489497E-09" izz="5.91969671305025E-07"/>
    </inertial>
    <visual>
      <origin rpy="0 0 0" xyz="0 0 0"/>
      <geometry>
        <mesh filename="package://walker_description/meshes/left_middle_l2.STL"/>
      </geometry>
      <material name="">
        <color rgba="0.752941176470588 0.752941176470588 0.752941176470588 1"/>
      </material>
    </visual>
    <collision>
      <origin rpy="1.5708 0 -0.1745" xyz="-0.002 -0.014 0.007"/>
      <geometry>
        <cylinder length="0.032" radius="0.010"/>
      </geometry>
    </collision>
  </link>
  <gazebo reference="left_middle_l2">
    <!-- <selfCollide>true</selfCollide>-->
    <material>Gazebo/White</material>
    <mu1>1000.0</mu1>
    <mu2>1000.0</mu2>
    <fdir1>0.0 0.0 1.0</fdir1>
    <kp>1e5</kp>
    <kd>1.0</kd>
  </gazebo>
  <joint name="left_middle_j2" type="revolute">
    <origin rpy="0.015814 0.0042886 1.7395" xyz="0.038459 0 -0.0122"/>
    <parent link="left_middle_l1"/>
    <child link="left_middle_l2"/>
    <axis xyz="-0.0042886 0.015813 -0.99987"/>
    <limit effort="1.0" lower="0" upper="1.5708" velocity="10"/>
    <dynamics damping="0.01" friction="0.0"/>
    <mimic joint="left_middle_j1" multiplier="1.0" offset="0.0"/>
  </joint>
  <gazebo reference="left_middle_j2">
    <implicitSpringDamper>true</implicitSpringDamper>
  </gazebo>
  <link name="left_ring_l1">
    <inertial>
      <origin rpy="0 0 0" xyz="0.0150066465487988 -0.000417740690980883 -0.00617161773568659"/>
      <mass value="0.00596757485212751"/>
      <inertia ixx="3.6154970839031E-07" ixy="1.12995090649401E-08" ixz="-9.55073355700821E-09" iyy="1.35207882018888E-06" iyz="3.71727201013289E-10" izz="1.37236862180291E-06"/>
    </inertial>
    <visual>
      <origin rpy="0 0 0" xyz="0 0 0"/>
      <geometry>
        <mesh filename="package://walker_description/meshes/left_ring_l1.STL"/>
      </geometry>
      <material name="">
        <color rgba="0.752941176470588 0.752941176470588 0.752941176470588 1"/>
      </material>
    </visual>
    <collision>
      <origin rpy="0 1.5708 0" xyz="0.014 0 -0.005"/>
      <geometry>
        <cylinder length="0.034" radius="0.010"/>
      </geometry>
    </collision>
  </link>
  <gazebo reference="left_ring_l1">
    <!-- <selfCollide>true</selfCollide>-->
  </gazebo>
  <joint name="left_ring_j1" type="revolute">
    <origin rpy="0.0058882 -0.015148 -1.6781" xyz="0.020863 -0.073224 0.013361"/>
    <parent link="left_palm_link"/>
    <child link="left_ring_l1"/>
    <axis xyz="1.7588E-05 0 -1"/>
    <limit effort="1.0" lower="0" upper="1.5708" velocity="10"/>
    <dynamics damping="0.01" friction="0.0"/>
  </joint>
  <gazebo reference="left_ring_j1">
    <implicitSpringDamper>true</implicitSpringDamper>
  </gazebo>
  <link name="left_ring_l2">
    <inertial>
      <origin rpy="0 0 0" xyz="-0.00178574011082344 -0.0099345155093529 0.0061186229082168"/>
      <mass value="0.00445721563393106"/>
      <inertia ixx="5.6496205492444E-07" ixy="-5.57715446692935E-08" ixz="8.36286600459378E-10" iyy="1.9706692522115E-07" iyz="6.65676794938147E-09" izz="5.97527568635283E-07"/>
    </inertial>
    <visual>
      <origin rpy="0 0 0" xyz="0 0 0"/>
      <geometry>
        <mesh filename="package://walker_description/meshes/left_ring_l2.STL"/>
      </geometry>
      <material name="">
        <color rgba="0.752941176470588 0.752941176470588 0.752941176470588 1"/>
      </material>
    </visual>
    <collision>
      <origin rpy="1.5708 0 -0.1745" xyz="-0.002 -0.014 0.007"/>
      <geometry>
        <cylinder length="0.032" radius="0.010"/>
      </geometry>
    </collision>
  </link>
  <gazebo reference="left_ring_l2">
    <!-- <selfCollide>true</selfCollide>-->
    <material>Gazebo/White</material>
    <mu1>1000.0</mu1>
    <mu2>1000.0</mu2>
    <fdir1>0.0 0.0 1.0</fdir1>
    <kp>1e5</kp>
    <kd>1.0</kd>
  </gazebo>
  <joint name="left_ring_j2" type="revolute">
    <origin rpy="0.015691 0.0042325 1.6781" xyz="0.038459 0 -0.012203"/>
    <parent link="left_ring_l1"/>
    <child link="left_ring_l2"/>
    <axis xyz="-0.0042344 0.015673 -0.99987"/>
    <limit effort="1.0" lower="0" upper="1.5708" velocity="10"/>
    <dynamics damping="0.01" friction="0.0"/>
    <mimic joint="left_ring_j1" multiplier="1.0" offset="0.0"/>
  </joint>
  <gazebo reference="left_ring_j2">
    <implicitSpringDamper>true</implicitSpringDamper>
  </gazebo>
  <link name="left_pinky_l1">
    <inertial>
      <origin rpy="0 0 0" xyz="0.0129948215470049 6.7441505780419E-05 -0.00569979807526588"/>
      <mass value="0.00474006684614483"/>
      <inertia ixx="2.40789497863744E-07" ixy="6.40265040823268E-09" ixz="2.07928316306501E-09" iyy="8.43737864578879E-07" iyz="7.44359550503124E-10" izz="8.5149387942E-07"/>
    </inertial>
    <visual>
      <origin rpy="0 0 0" xyz="0 0 0"/>
      <geometry>
        <mesh filename="package://walker_description/meshes/left_pinky_l1.STL"/>
      </geometry>
      <material name="">
        <color rgba="0.752941176470588 0.752941176470588 0.752941176470588 1"/>
      </material>
    </visual>
    <collision>
      <origin rpy="0 1.5708 0" xyz="0.014 0 -0.005"/>
      <geometry>
        <cylinder length="0.034" radius="0.010"/>
      </geometry>
    </collision>
  </link>
  <gazebo reference="left_pinky_l1">
    <!-- <selfCollide>true</selfCollide>-->
  </gazebo>
  <joint name="left_pinky_j1" type="revolute">
    <origin rpy="-0.034105 -0.016248 -1.6441" xyz="0.021779 -0.069944 -0.010184"/>
    <parent link="left_palm_link"/>
    <child link="left_pinky_l1"/>
    <axis xyz="6.6172E-05 0 -1"/>
    <limit effort="1.0" lower="0" upper="1.5708" velocity="10"/>
    <dynamics damping="0.01" friction="0.0"/>
    <mimic joint="left_ring_j1" multiplier="1.0" offset="0.0"/>
  </joint>
  <gazebo reference="left_pinky_j1">
    <implicitSpringDamper>true</implicitSpringDamper>
  </gazebo>
  <link name="left_pinky_l2">
    <inertial>
      <origin rpy="0 0 0" xyz="-0.00207317179159261 -0.0122243534973791 -0.00503143611359247"/>
      <mass value="0.00390644847680527"/>
      <inertia ixx="5.18285631399026E-07" ixy="-5.55253133559814E-08" ixz="2.07796178117026E-09" iyy="1.49229602527441E-07" iyz="9.30943070175501E-09" izz="5.41041706459008E-07"/>
    </inertial>
    <visual>
      <origin rpy="0 0 0" xyz="0 0 0"/>
      <geometry>
        <mesh filename="package://walker_description/meshes/left_pinky_l2.STL"/>
      </geometry>
      <material name="">
        <color rgba="0.752941176470588 0.752941176470588 0.752941176470588 1"/>
      </material>
    </visual>
    <collision>
      <origin rpy="1.5708 0 -0.1745" xyz="-0.004 -0.020 -0.005"/>
      <geometry>
        <cylinder length="0.032" radius="0.010"/>
      </geometry>
    </collision>
  </link>
  <gazebo reference="left_pinky_l2">
    <!-- <selfCollide>true</selfCollide>-->
    <material>Gazebo/White</material>
    <mu1>1000.0</mu1>
    <mu2>1000.0</mu2>
    <fdir1>0.0 0.0 1.0</fdir1>
    <kp>1e5</kp>
    <kd>1.0</kd>
  </gazebo>
  <joint name="left_pinky_j2" type="revolute">
    <origin rpy="0.013704 -0.035204 1.6442" xyz="0.03311 0.00034528 -0.00040579"/>
    <parent link="left_pinky_l1"/>
    <child link="left_pinky_l2"/>
    <axis xyz="0.035197 0.013623 -0.99929"/>
    <limit effort="1.0" lower="0" upper="1.5708" velocity="10"/>
    <dynamics damping="0.01" friction="0.0"/>
    <mimic joint="left_ring_j1" multiplier="1.0" offset="0.0"/>
  </joint>
  <gazebo reference="left_pinky_j2">
    <implicitSpringDamper>true</implicitSpringDamper>
  </gazebo>
  <gazebo>
    <plugin filename="libroboticsgroup_gazebo_mimic_joint_plugin.so" name="left_thumb_j2mimic_joint_plugin">
      <joint>left_thumb_j1</joint>
      <mimicJoint>left_thumb_j2</mimicJoint>
      <multiplier>1.0</multiplier>
      <offset>0.0</offset>
    </plugin>
  </gazebo>
  <gazebo>
    <plugin filename="libroboticsgroup_gazebo_mimic_joint_plugin.so" name="left_index_j2mimic_joint_plugin">
      <joint>left_index_j1</joint>
      <mimicJoint>left_index_j2</mimicJoint>
      <multiplier>1.0</multiplier>
      <offset>0.0</offset>
    </plugin>
  </gazebo>
  <gazebo>
    <plugin filename="libroboticsgroup_gazebo_mimic_joint_plugin.so" name="left_middle_j2mimic_joint_plugin">
      <joint>left_middle_j1</joint>
      <mimicJoint>left_middle_j2</mimicJoint>
      <multiplier>1.0</multiplier>
      <offset>0.0</offset>
    </plugin>
  </gazebo>
  <gazebo>
    <plugin filename="libroboticsgroup_gazebo_mimic_joint_plugin.so" name="left_ring_j2mimic_joint_plugin">
      <joint>left_ring_j1</joint>
      <mimicJoint>left_ring_j2</mimicJoint>
      <multiplier>1.0</multiplier>
      <offset>0.0</offset>
    </plugin>
  </gazebo>
  <gazebo>
    <plugin filename="libroboticsgroup_gazebo_mimic_joint_plugin.so" name="left_pinky_j1mimic_joint_plugin">
      <joint>left_ring_j1</joint>
      <mimicJoint>left_pinky_j1</mimicJoint>
      <multiplier>1.0</multiplier>
      <offset>0.0</offset>
    </plugin>
  </gazebo>
  <gazebo>
    <plugin filename="libroboticsgroup_gazebo_mimic_joint_plugin.so" name="left_pinky_j2mimic_joint_plugin">
      <joint>left_ring_j1</joint>
      <mimicJoint>left_pinky_j2</mimicJoint>
      <multiplier>1.0</multiplier>
      <offset>0.0</offset>
    </plugin>
  </gazebo>
  <transmission name="left_thumb_tran1">
    <type>transmission_interface/SimpleTransmission</type>
    <joint name="left_thumb_j1">
      <hardwareInterface>EffortJointInterface</hardwareInterface>
    </joint>
    <actuator name="left_thumb_motor1">
      <hardwareInterface>EffortJointInterface</hardwareInterface>
      <mechanicalReduction>1</mechanicalReduction>
    </actuator>
  </transmission>
  <transmission name="left_index_tran1">
    <type>transmission_interface/SimpleTransmission</type>
    <joint name="left_index_j1">
      <hardwareInterface>EffortJointInterface</hardwareInterface>
    </joint>
    <actuator name="left_index_motor1">
      <hardwareInterface>EffortJointInterface</hardwareInterface>
      <mechanicalReduction>1</mechanicalReduction>
    </actuator>
  </transmission>
  <transmission name="left_middle_tran1">
    <type>transmission_interface/SimpleTransmission</type>
    <joint name="left_middle_j1">
      <hardwareInterface>EffortJointInterface</hardwareInterface>
    </joint>
    <actuator name="left_middle_motor1">
      <hardwareInterface>EffortJointInterface</hardwareInterface>
      <mechanicalReduction>1</mechanicalReduction>
    </actuator>
  </transmission>
  <transmission name="left_ring_tran1">
    <type>transmission_interface/SimpleTransmission</type>
    <joint name="left_ring_j1">
      <hardwareInterface>EffortJointInterface</hardwareInterface>
    </joint>
    <actuator name="left_ring_motor1">
      <hardwareInterface>EffortJointInterface</hardwareInterface>
      <mechanicalReduction>1</mechanicalReduction>
    </actuator>
  </transmission>
  <link name="right_palm_link">
    <inertial>
      <origin rpy="0 0 0" xyz="-0.0144809215118954 -0.0132347085538364 0.022306335464008"/>
      <mass value="0.0852752510078387"/>
      <inertia ixx="0.000154775131402232" ixy="1.85109602266807E-05" ixz="7.47252049170957E-06" iyy="0.000107981762301999" iyz="-1.08345230717271E-06" izz="0.000125562926987643"/>
    </inertial>
    <visual>
      <origin rpy="0 0 0" xyz="0 0 0"/>
      <geometry>
        <mesh filename="package://walker_description/meshes/right_palm_link.STL"/>
      </geometry>
      <material name="">
        <color rgba="0.752941176470588 0.752941176470588 0.752941176470588 1"/>
      </material>
    </visual>
    <collision>
      <origin rpy="0 0 0" xyz="-0.020 -0.005 0.020"/>
      <geometry>
        <box size="0.040 0.090 0.100"/>
      </geometry>
    </collision>
  </link>
  <gazebo reference="right_palm_link">
    <!-- <selfCollide>true</selfCollide>-->
    <material>Gazebo/White</material>
    <mu1>1000.0</mu1>
    <mu2>1000.0</mu2>
    <fdir1>0.0 0.0 1.0</fdir1>
    <kp>1e5</kp>
    <kd>1.0</kd>
  </gazebo>
  <joint name="right_palm_joint" type="fixed">
    <origin rpy="-1.0945E-07 -1.947E-07 1.8326" xyz="0.0720 0.011942 -0.02228"/>
    <!--rpy="0 0 1.7826, 8326 "0.074796 0.011942 -0.02228"-->
    <parent link="right_limb_l7"/>
    <child link="right_palm_link"/>
    <axis xyz="0 0 0"/>
  </joint>
  <gazebo reference="right_palm_joint">
    <implicitSpringDamper>true</implicitSpringDamper>
  </gazebo>
  <link name="right_thumb_l1">
    <inertial>
      <origin rpy="0 0 0" xyz="0.0109078578963968 -0.000509975490591813 -0.00754093105655529"/>
      <mass value="0.00861449029296223"/>
      <inertia ixx="6.47380528453408E-07" ixy="2.31441793919066E-08" ixz="-4.86167105843724E-09" iyy="1.90689640236326E-06" iyz="-1.39055202752738E-09" izz="1.9883580412794E-06"/>
    </inertial>
    <visual>
      <origin rpy="0 0 0" xyz="0 0 0"/>
      <geometry>
        <mesh filename="package://walker_description/meshes/right_thumb_l1.STL"/>
      </geometry>
      <material name="">
        <color rgba="0.752941176470588 0.752941176470588 0.752941176470588 1"/>
      </material>
    </visual>
    <collision>
      <origin rpy="0 1.5708 0" xyz="0.008 -0.001 -0.008"/>
      <geometry>
        <cylinder length="0.028" radius="0.012"/>
      </geometry>
    </collision>
  </link>
  <gazebo reference="right_thumb_l1">
    <!-- <selfCollide>true</selfCollide>-->
  </gazebo>
  <joint name="right_thumb_j1" type="revolute">
    <origin rpy="0.2841 0.15098 -0.74405" xyz="0.029243 -0.01232 0.046918"/>
    <parent link="right_palm_link"/>
    <child link="right_thumb_l1"/>
    <axis xyz="0 0 -1"/>
    <limit effort="1.0" lower="0" upper="1.5708" velocity="10"/>
    <dynamics damping="0.01" friction="0.0"/>
  </joint>
  <gazebo reference="right_thumb_j1">
    <implicitSpringDamper>true</implicitSpringDamper>
  </gazebo>
  <link name="right_thumb_l2">
    <inertial>
      <origin rpy="0 0 0" xyz="0.0038139122437023 -0.00519298982364705 0.00691359394439273"/>
      <mass value="0.00424317818671721"/>
      <inertia ixx="3.5640013810942E-07" ixy="1.05147480910049E-07" ixz="8.76003562788286E-10" iyy="2.70951305064946E-07" iyz="-1.69974504756699E-09" izz="4.26072223593812E-07"/>
    </inertial>
    <visual>
      <origin rpy="0 0 0" xyz="0 0 0"/>
      <geometry>
        <mesh filename="package://walker_description/meshes/right_thumb_l2.STL"/>
      </geometry>
      <material name="">
        <color rgba="0.752941176470588 0.752941176470588 0.752941176470588 1"/>
      </material>
    </visual>
    <collision>
      <origin rpy="0 1.5708 -0.7854" xyz="0.007 -0.009 0.007"/>
      <geometry>
        <cylinder length="0.025" radius="0.012"/>
      </geometry>
    </collision>
  </link>
  <gazebo reference="right_thumb_l2">
    <!-- <selfCollide>true</selfCollide>-->
    <material>Gazebo/White</material>
    <mu1>1000.0</mu1>
    <mu2>1000.0</mu2>
    <fdir1>0.0 0.0 1.0</fdir1>
    <kp>1e5</kp>
    <kd>1.0</kd>
  </gazebo>
  <joint name="right_thumb_j2" type="revolute">
    <origin rpy="-9.1041E-12 5.5133E-12 0.77938" xyz="0.03655 0 -0.014481"/>
    <parent link="right_thumb_l1"/>
    <child link="right_thumb_l2"/>
    <axis xyz="0 0 -1"/>
    <limit effort="1.0" lower="0" upper="1.5708" velocity="10"/>
    <dynamics damping="0.01" friction="0.0"/>
    <mimic joint="right_thumb_j1" multiplier="1.0" offset="0.0"/>
  </joint>
  <gazebo reference="right_thumb_j2">
    <implicitSpringDamper>true</implicitSpringDamper>
  </gazebo>
  <link name="right_index_l1">
    <inertial>
      <origin rpy="0 0 0" xyz="0.0152771482029122 0.000408639325090332 -0.00626307273726445"/>
      <mass value="0.00605247314202731"/>
      <inertia ixx="3.65783992375028E-07" ixy="-1.00934807957291E-08" ixz="2.80428619617228E-09" iyy="1.39916151323369E-06" iyz="-6.9923785252466E-10" izz="1.41553939969596E-06"/>
    </inertial>
    <visual>
      <origin rpy="0 0 0" xyz="0 0 0"/>
      <geometry>
        <mesh filename="package://walker_description/meshes/right_index_l1.STL"/>
      </geometry>
      <material name="">
        <color rgba="0.752941176470588 0.752941176470588 0.752941176470588 1"/>
      </material>
    </visual>
    <collision>
      <origin rpy="0 1.5708 0" xyz="0.014 0 -0.007"/>
      <geometry>
        <cylinder length="0.034" radius="0.010"/>
      </geometry>
    </collision>
  </link>
  <gazebo reference="right_index_l1">
    <!-- <selfCollide>true</selfCollide>-->
  </gazebo>
  <joint name="right_index_j1" type="revolute">
    <origin rpy="0.02196 0.053684 -1.3927" xyz="-0.017699 -0.07587 0.055574"/>
    <parent link="right_palm_link"/>
    <child link="right_index_l1"/>
    <axis xyz="0 0 1"/>
    <limit effort="1.0" lower="0" upper="1.5708" velocity="10"/>
    <dynamics damping="0.01" friction="0.0"/>
  </joint>
  <gazebo reference="right_index_j1">
    <implicitSpringDamper>true</implicitSpringDamper>
  </gazebo>
  <link name="right_index_l2">
    <inertial>
      <origin rpy="0 0 0" xyz="0.00234422723007119 -0.0102129867424652 0.00542736940606858"/>
      <mass value="0.00445698708822686"/>
      <inertia ixx="5.55945076014283E-07" ixy="7.93649952032288E-08" ixz="3.91934574204375E-09" iyy="2.06935930101655E-07" iyz="-2.05205145649726E-08" izz="5.96534224716826E-07"/>
    </inertial>
    <visual>
      <origin rpy="0 0 0" xyz="0 0 0"/>
      <geometry>
        <mesh filename="package://walker_description/meshes/right_index_l2.STL"/>
      </geometry>
      <material name="">
        <color rgba="0.752941176470588 0.752941176470588 0.752941176470588 1"/>
      </material>
    </visual>
    <collision>
      <origin rpy="1.5708 0 0.1745" xyz="0.002 -0.014 0.005"/>
      <geometry>
        <cylinder length="0.032" radius="0.010"/>
      </geometry>
    </collision>
  </link>
  <gazebo reference="right_index_l2">
    <!-- <selfCollide>true</selfCollide>-->
    <material>Gazebo/White</material>
    <mu1>1000.0</mu1>
    <mu2>1000.0</mu2>
    <fdir1>0.0 0.0 1.0</fdir1>
    <kp>1e5</kp>
    <kd>1.0</kd>
  </gazebo>
  <joint name="right_index_j2" type="revolute">
    <origin rpy="-0.056721 0.01211 1.393" xyz="0.038459 0 -0.012377"/>
    <parent link="right_index_l1"/>
    <child link="right_index_l2"/>
    <axis xyz="-0.01211 -0.056687 0.99832"/>
    <limit effort="1.0" lower="0" upper="1.5708" velocity="10"/>
    <dynamics damping="0.01" friction="0.0"/>
    <mimic joint="right_index_j1" multiplier="1.0" offset="0.0"/>
  </joint>
  <gazebo reference="right_index_j2">
    <implicitSpringDamper>true</implicitSpringDamper>
  </gazebo>
  <link name="right_middle_l1">
    <inertial>
      <origin rpy="0 0 0" xyz="0.0152762687335811 0.000409441523501169 -0.00626287883593529"/>
      <mass value="0.00605245451819771"/>
      <inertia ixx="3.65760702571658E-07" ixy="-1.01893397954424E-08" ixz="2.77675028804505E-09" iyy="1.39915356053442E-06" iyz="-7.67361702883963E-10" izz="1.41551554295189E-06"/>
    </inertial>
    <visual>
      <origin rpy="0 0 0" xyz="0 0 0"/>
      <geometry>
        <mesh filename="package://walker_description/meshes/right_middle_l1.STL"/>
      </geometry>
      <material name="">
        <color rgba="0.752941176470588 0.752941176470588 0.752941176470588 1"/>
      </material>
    </visual>
    <collision>
      <origin rpy="0 1.5708 0" xyz="0.014 0 -0.007"/>
      <geometry>
        <cylinder length="0.034" radius="0.010"/>
      </geometry>
    </collision>
  </link>
  <gazebo reference="right_middle_l1">
    <!-- <selfCollide>true</selfCollide>-->
  </gazebo>
  <joint name="right_middle_j1" type="revolute">
    <origin rpy="0.025306 0.052053 -1.3281" xyz="-0.018928 -0.080828 0.031376"/>
    <parent link="right_palm_link"/>
    <child link="right_middle_l1"/>
    <axis xyz="0 0 1"/>
    <limit effort="1.0" lower="0" upper="1.5708" velocity="10"/>
    <dynamics damping="0.01" friction="0.0"/>
  </joint>
  <gazebo reference="right_middle_j1">
    <implicitSpringDamper>true</implicitSpringDamper>
  </gazebo>
  <link name="right_middle_l2">
    <inertial>
      <origin rpy="0 0 0" xyz="0.00289048514159018 -0.0100490531988506 0.00544431144992846"/>
      <mass value="0.00445696556461065"/>
      <inertia ixx="5.45564758790963E-07" ixy="9.81535413955714E-08" ixz="4.85238074391545E-09" iyy="2.11707171087764E-07" iyz="-1.96865301788014E-08" izz="5.91025277276737E-07"/>
    </inertial>
    <visual>
      <origin rpy="0 0 0" xyz="0 0 0"/>
      <geometry>
        <mesh filename="package://walker_description/meshes/right_middle_l2.STL"/>
      </geometry>
      <material name="">
        <color rgba="0.752941176470588 0.752941176470588 0.752941176470588 1"/>
      </material>
    </visual>
    <collision>
      <origin rpy="1.5708 0 0.1745" xyz="0.002 -0.014 0.005"/>
      <geometry>
        <cylinder length="0.032" radius="0.010"/>
      </geometry>
    </collision>
  </link>
  <gazebo reference="right_middle_l2">
    <!-- <selfCollide>true</selfCollide>-->
    <material>Gazebo/White</material>
    <mu1>1000.0</mu1>
    <mu2>1000.0</mu2>
    <fdir1>0.0 0.0 1.0</fdir1>
    <kp>1e5</kp>
    <kd>1.0</kd>
  </gazebo>
  <joint name="right_middle_j2" type="revolute">
    <origin rpy="-0.056603 0.012064 1.3285" xyz="0.038459 0 -0.0122"/>
    <parent link="right_middle_l1"/>
    <child link="right_middle_l2"/>
    <axis xyz="-0.012065 -0.056562 0.99833"/>
    <limit effort="1.0" lower="0" upper="1.5708" velocity="10"/>
    <dynamics damping="0.01" friction="0.0"/>
    <mimic joint="right_middle_j1" multiplier="1.0" offset="0.0"/>
  </joint>
  <gazebo reference="right_middle_j2">
    <implicitSpringDamper>true</implicitSpringDamper>
  </gazebo>
  <link name="right_ring_l1">
    <inertial>
      <origin rpy="0 0 0" xyz="0.0152790983713928 -0.000407929740707025 0.00626138266965892"/>
      <mass value="0.00605247678962561"/>
      <inertia ixx="3.65675226655157E-07" ixy="1.01164336091825E-08" ixz="-2.81242513232345E-09" iyy="1.39904698102302E-06" iyz="-7.46466225242176E-10" izz="1.41555060676411E-06"/>
    </inertial>
    <visual>
      <origin rpy="0 0 0" xyz="0 0 0"/>
      <geometry>
        <mesh filename="package://walker_description/meshes/right_ring_l1.STL"/>
      </geometry>
      <material name="">
        <color rgba="0.752941176470588 0.752941176470588 0.752941176470588 1"/>
      </material>
    </visual>
    <collision>
      <origin rpy="0 1.5708 0" xyz="0.014 0 0.007"/>
      <geometry>
        <cylinder length="0.034" radius="0.010"/>
      </geometry>
    </collision>
  </link>
  <gazebo reference="right_ring_l1">
    <!-- <selfCollide>true</selfCollide>-->
  </gazebo>
  <joint name="right_ring_j1" type="revolute">
    <origin rpy="-3.1203 0.05396 -1.4056" xyz="-0.017845 -0.074821 0.007677"/>
    <parent link="right_palm_link"/>
    <child link="right_ring_l1"/>
    <axis xyz="1.7588E-05 0 -1"/>
    <limit effort="1.0" lower="0" upper="1.5708" velocity="10"/>
    <dynamics damping="0.01" friction="0.0"/>
  </joint>
  <gazebo reference="right_ring_j1">
    <implicitSpringDamper>true</implicitSpringDamper>
  </gazebo>
  <link name="right_ring_l2">
    <inertial>
      <origin rpy="0 0 0" xyz="0.00226446203390765 -0.0102341141638748 0.00542585656729089"/>
      <mass value="0.00445699860314573"/>
      <inertia ixx="5.57270584510554E-07" ixy="7.65166590723597E-08" ixz="3.78737544474429E-09" iyy="2.05690510460265E-07" iyz="-2.06747876235999E-08" izz="5.96524268555039E-07"/>
    </inertial>
    <visual>
      <origin rpy="0 0 0" xyz="0 0 0"/>
      <geometry>
        <mesh filename="package://walker_description/meshes/right_ring_l2.STL"/>
      </geometry>
      <material name="">
        <color rgba="0.752941176470588 0.752941176470588 0.752941176470588 1"/>
      </material>
    </visual>
    <collision>
      <origin rpy="1.5708 0 0.1745" xyz="0.002 -0.014 0.005"/>
      <geometry>
        <cylinder length="0.032" radius="0.010"/>
      </geometry>
    </collision>
  </link>
  <gazebo reference="right_ring_l2">
    <!-- <selfCollide>true</selfCollide>-->
    <material>Gazebo/White</material>
    <mu1>1000.0</mu1>
    <mu2>1000.0</mu2>
    <fdir1>0.0 0.0 1.0</fdir1>
    <kp>1e5</kp>
    <kd>1.0</kd>
  </gazebo>
  <joint name="right_ring_j2" type="revolute">
    <origin rpy="3.0849 -0.012117 -1.4058" xyz="0.038461 0 0.012203"/>
    <parent link="right_ring_l1"/>
    <child link="right_ring_l2"/>
    <axis xyz="-0.012113 -0.056705 0.99832"/>
    <limit effort="1.0" lower="0" upper="1.5708" velocity="10"/>
    <dynamics damping="0.01" friction="0.0"/>
    <mimic joint="right_ring_j1" multiplier="1.0" offset="0.0"/>
  </joint>
  <gazebo reference="right_ring_j2">
    <implicitSpringDamper>true</implicitSpringDamper>
  </gazebo>
  <link name="right_pinky_l1">
    <inertial>
      <origin rpy="0 0 0" xyz="0.0136417719935673 -0.000125531934202894 -0.00569767013320738"/>
      <mass value="0.00475338387931075"/>
      <inertia ixx="2.41836333046606E-07" ixy="-7.21453266409586E-09" ixz="2.18288517443966E-09" iyy="8.45647103827569E-07" iyz="-5.90210689072676E-10" izz="8.54135009354068E-07"/>
    </inertial>
    <visual>
      <origin rpy="0 0 0" xyz="0 0 0"/>
      <geometry>
        <mesh filename="package://walker_description/meshes/right_pinky_l1.STL"/>
      </geometry>
      <material name="">
        <color rgba="0.752941176470588 0.752941176470588 0.752941176470588 1"/>
      </material>
    </visual>
    <collision>
      <origin rpy="0 1.5708 0" xyz="0.014 0 -0.007"/>
      <geometry>
        <cylinder length="0.034" radius="0.010"/>
      </geometry>
    </collision>
  </link>
  <gazebo reference="right_pinky_l1">
    <!-- <selfCollide>true</selfCollide>-->
  </gazebo>
  <joint name="right_pinky_j1" type="revolute">
    <origin rpy="0.063832 0.04715 -1.3412" xyz="-0.018167 -0.069717 -0.015649"/>
    <parent link="right_palm_link"/>
    <child link="right_pinky_l1"/>
    <axis xyz="5.8842E-05 0 1"/>
    <limit effort="1.0" lower="0" upper="1.5708" velocity="10"/>
    <dynamics damping="0.01" friction="0.0"/>
    <mimic joint="right_ring_j1" multiplier="1.0" offset="0.0"/>
  </joint>
  <gazebo reference="right_pinky_j1">
    <implicitSpringDamper>true</implicitSpringDamper>
  </gazebo>
  <link name="right_pinky_l2">
    <inertial>
      <origin rpy="0 0 0" xyz="0.00385750559999914 -0.0117317540747605 0.00513394348644691"/>
      <mass value="0.00390662275645989"/>
      <inertia ixx="4.90879392525086E-07" ixy="1.11650195510708E-07" ixz="-8.41646328987664E-10" iyy="1.76444115028913E-07" iyz="1.94024217356653E-09" izz="5.41362797182644E-07"/>
    </inertial>
    <visual>
      <origin rpy="0 0 0" xyz="0 0 0"/>
      <geometry>
        <mesh filename="package://walker_description/meshes/right_pinky_l2.STL"/>
      </geometry>
      <material name="">
        <color rgba="0.752941176470588 0.752941176470588 0.752941176470588 1"/>
      </material>
    </visual>
    <collision>
      <origin rpy="1.5708 0 0.1745" xyz="0.002 -0.018 0.004"/>
      <geometry>
        <cylinder length="0.032" radius="0.010"/>
      </geometry>
    </collision>
  </link>
  <gazebo reference="right_pinky_l2">
    <!-- <selfCollide>true</selfCollide>-->
    <material>Gazebo/White</material>
    <mu1>1000.0</mu1>
    <mu2>1000.0</mu2>
    <fdir1>0.0 0.0 1.0</fdir1>
    <kp>1e5</kp>
    <kd>1.0</kd>
  </gazebo>
  <joint name="right_pinky_j2" type="revolute">
    <origin rpy="7.2607E-05 6.2497E-06 1.3443" xyz="0.033786 -0.00038214 -0.010543"/>
    <parent link="right_pinky_l1"/>
    <child link="right_pinky_l2"/>
    <axis xyz="0 0 1"/>
    <limit effort="1.0" lower="0" upper="1.5708" velocity="10"/>
    <dynamics damping="0.01" friction="0.0"/>
    <mimic joint="right_ring_j1" multiplier="1.0" offset="0.0"/>
  </joint>
  <gazebo reference="right_pinky_j2">
    <implicitSpringDamper>true</implicitSpringDamper>
  </gazebo>
  <gazebo>
    <plugin filename="libroboticsgroup_gazebo_mimic_joint_plugin.so" name="right_thumb_j2mimic_joint_plugin">
      <joint>right_thumb_j1</joint>
      <mimicJoint>right_thumb_j2</mimicJoint>
      <multiplier>1.0</multiplier>
      <offset>0.0</offset>
    </plugin>
  </gazebo>
  <gazebo>
    <plugin filename="libroboticsgroup_gazebo_mimic_joint_plugin.so" name="right_index_j2mimic_joint_plugin">
      <joint>right_index_j1</joint>
      <mimicJoint>right_index_j2</mimicJoint>
      <multiplier>1.0</multiplier>
      <offset>0.0</offset>
    </plugin>
  </gazebo>
  <gazebo>
    <plugin filename="libroboticsgroup_gazebo_mimic_joint_plugin.so" name="right_middle_j2mimic_joint_plugin">
      <joint>right_middle_j1</joint>
      <mimicJoint>right_middle_j2</mimicJoint>
      <multiplier>1.0</multiplier>
      <offset>0.0</offset>
    </plugin>
  </gazebo>
  <gazebo>
    <plugin filename="libroboticsgroup_gazebo_mimic_joint_plugin.so" name="right_ring_j2mimic_joint_plugin">
      <joint>right_ring_j1</joint>
      <mimicJoint>right_ring_j2</mimicJoint>
      <multiplier>1.0</multiplier>
      <offset>0.0</offset>
    </plugin>
  </gazebo>
  <gazebo>
    <plugin filename="libroboticsgroup_gazebo_mimic_joint_plugin.so" name="right_pinky_j1mimic_joint_plugin">
      <joint>right_ring_j1</joint>
      <mimicJoint>right_pinky_j1</mimicJoint>
      <multiplier>1.0</multiplier>
      <offset>0.0</offset>
    </plugin>
  </gazebo>
  <gazebo>
    <plugin filename="libroboticsgroup_gazebo_mimic_joint_plugin.so" name="right_pinky_j2mimic_joint_plugin">
      <joint>right_ring_j1</joint>
      <mimicJoint>right_pinky_j2</mimicJoint>
      <multiplier>1.0</multiplier>
      <offset>0.0</offset>
    </plugin>
  </gazebo>
  <transmission name="right_thumb_tran1">
    <type>transmission_interface/SimpleTransmission</type>
    <joint name="right_thumb_j1">
      <hardwareInterface>EffortJointInterface</hardwareInterface>
    </joint>
    <actuator name="right_thumb_motor1">
      <hardwareInterface>EffortJointInterface</hardwareInterface>
      <mechanicalReduction>1</mechanicalReduction>
    </actuator>
  </transmission>
  <transmission name="right_index_tran1">
    <type>transmission_interface/SimpleTransmission</type>
    <joint name="right_index_j1">
      <hardwareInterface>EffortJointInterface</hardwareInterface>
    </joint>
    <actuator name="right_index_motor1">
      <hardwareInterface>EffortJointInterface</hardwareInterface>
      <mechanicalReduction>1</mechanicalReduction>
    </actuator>
  </transmission>
  <transmission name="right_middle_tran1">
    <type>transmission_interface/SimpleTransmission</type>
    <joint name="right_middle_j1">
      <hardwareInterface>EffortJointInterface</hardwareInterface>
    </joint>
    <actuator name="right_middle_motor1">
      <hardwareInterface>EffortJointInterface</hardwareInterface>
      <mechanicalReduction>1</mechanicalReduction>
    </actuator>
  </transmission>
  <transmission name="right_ring_tran1">
    <type>transmission_interface/SimpleTransmission</type>
    <joint name="right_ring_j1">
      <hardwareInterface>EffortJointInterface</hardwareInterface>
    </joint>
    <actuator name="right_ring_motor1">
      <hardwareInterface>EffortJointInterface</hardwareInterface>
      <mechanicalReduction>1</mechanicalReduction>
    </actuator>
  </transmission>
  <link name="left_leg_l1">
    <inertial>
      <origin rpy="0 0 0" xyz="-5.11729121482896E-06 0.00936420392659237 -0.0512174071313175"/>
      <mass value="0.319858278400239"/>
      <inertia ixx="0.00254235702064034" ixy="1.57444035565856E-07" ixz="6.65716426297689E-08" iyy="0.000943857844567228" iyz="-4.8242552258139E-05" izz="0.00197157321730625"/>
    </inertial>
    <visual>
      <origin rpy="0 0 0" xyz="0 0 0"/>
      <geometry>
        <mesh filename="package://walker_description/meshes/left_leg_l1.STL"/>
      </geometry>
      <material name="">
        <color rgba="0.752941176470588 0.752941176470588 0.752941176470588 1"/>
      </material>
    </visual>
    <!--<collision>
      <origin xyz="0 0 0" rpy="0 1.5708 0" />
      <geometry>
        <cylinder length="0.105" radius="0.125"/>
      </geometry>
    </collision>-->
  </link>
  <gazebo reference="left_leg_l1">
    <!-- <selfCollide>true</selfCollide>-->
  </gazebo>
  <joint name="left_leg_j1" type="revolute">
    <origin rpy="3.1416 -0.0016575 1.5708" xyz="0 0.110 -0.43677"/>
    <parent link="base_link"/>
    <child link="left_leg_l1"/>
    <axis xyz="0 0 -1"/>
    <limit effort="30.0" lower="-1.0472" upper="1.0472" velocity="2.0944"/>
    <dynamics damping="15" friction="0.0"/>
  </joint>
  <gazebo reference="left_leg_j1">
    <implicitSpringDamper>true</implicitSpringDamper>
  </gazebo>
  <link name="left_leg_l2">
    <inertial>
      <origin rpy="0 0 0" xyz="-2.80791043859308E-06 -5.52021585495388E-05 -0.00165084747917332"/>
      <mass value="0.267356799799025"/>
      <inertia ixx="0.00124886157714483" ixy="-1.26116836235828E-07" ixz="-5.58754914571502E-08" iyy="0.00186090476591849" iyz="1.08419803614328E-06" izz="0.00155478511176639"/>
    </inertial>
    <visual>
      <origin rpy="0 0 0" xyz="0 0 0"/>
      <geometry>
        <mesh filename="package://walker_description/meshes/left_leg_l2.STL"/>
      </geometry>
      <material name="">
        <color rgba="0.752941176470588 0.752941176470588 0.752941176470588 1"/>
      </material>
    </visual>
    <!--<collision>
      <origin xyz="0 0 0" rpy="1.5708 0 0" />
      <geometry>
        <cylinder length="0.120" radius="0.105"/>
      </geometry>
    </collision>-->
  </link>
  <gazebo reference="left_leg_l2">
    <!-- <selfCollide>true</selfCollide>-->
  </gazebo>
  <joint name="left_leg_j2" type="revolute">
    <origin rpy="1.5708 -1.5708 0" xyz="0 0 0"/>
    <parent link="left_leg_l1"/>
    <child link="left_leg_l2"/>
    <axis xyz="0 0 -1"/>
    <limit effort="25.0" lower="-0.5236" upper="0.5236" velocity="3.1416"/>
    <dynamics damping="8.0" friction="0.0"/>
  </joint>
  <gazebo reference="left_leg_j2">
    <implicitSpringDamper>true</implicitSpringDamper>
  </gazebo>
  <link name="left_leg_l3">
    <inertial>
      <origin rpy="0 0 0" xyz="-2.8079104386243E-06 0.00165084747917321 -5.52021585495943E-05"/>
      <mass value="0.267356799799025"/>
      <inertia ixx="0.00124886157714483" ixy="5.587549145688E-08" ixz="-1.2611683623583E-07" iyy="0.00155478511176639" iyz="-1.08419803614328E-06" izz="0.00186090476591848"/>
    </inertial>
    <visual>
      <origin rpy="0 0 0" xyz="0 0 0"/>
      <geometry>
        <mesh filename="package://walker_description/meshes/left_leg_l3.STL"/>
      </geometry>
      <material name="">
        <color rgba="0.752941176470588 0.752941176470588 0.752941176470588 1"/>
      </material>
    </visual>
    <!--<collision>
      <origin xyz="0 0 0" rpy="0 0 0" />
      <geometry>
        <cylinder length="0.120" radius="0.105"/>
      </geometry>
    </collision>-->
  </link>
  <gazebo reference="left_leg_l3">
    <!-- <selfCollide>true</selfCollide>-->
  </gazebo>
  <joint name="left_leg_j3" type="revolute">
    <origin rpy="1.5708 0 1.5647E-33" xyz="0 0 0"/>
    <parent link="left_leg_l2"/>
    <child link="left_leg_l3"/>
    <axis xyz="0 0 1"/>
    <limit effort="15.0" lower="-1.3963" upper="0.5236" velocity="3.1416"/>
    <dynamics damping="5.0" friction="0.0"/>
  </joint>
  <gazebo reference="left_leg_j3">
    <implicitSpringDamper>true</implicitSpringDamper>
  </gazebo>
  <link name="left_leg_link1">
    <inertial>
      <origin rpy="0 0 0" xyz="0.00144392186031084 -0.0169601633210854 -0.00169801629659916"/>
      <mass value="0.685984085787246"/>
      <inertia ixx="0.00956077848823135" ixy="-4.83564083228453E-05" ixz="-1.12762450536806E-05" iyy="0.00493338150806551" iyz="0.000203803662618588" izz="0.0117303046260317"/>
    </inertial>
    <visual>
      <origin rpy="0 0 0" xyz="0 0 0"/>
      <geometry>
        <mesh filename="package://walker_description/meshes/left_leg_link1.STL"/>
      </geometry>
      <material name="">
        <color rgba="0.752941176470588 0.752941176470588 0.752941176470588 1"/>
      </material>
    </visual>
    <collision>
      <origin rpy="1.5708 0 0" xyz="0 -0.025 0"/>
      <geometry>
        <cylinder length="0.430" radius="0.090"/>
      </geometry>
    </collision>
  </link>
  <gazebo reference="left_leg_link1">
    <!-- <selfCollide>true</selfCollide>-->
  </gazebo>
  <joint name="left_leg_joint1" type="fixed">
    <origin rpy="1.5708 -1.5708 0" xyz="0.10911 -0.011583 -0.00049937"/>
    <parent link="left_leg_l3"/>
    <child link="left_leg_link1"/>
    <axis xyz="0 0 0"/>
  </joint>
  <gazebo reference="left_leg_joint1">
    <implicitSpringDamper>true</implicitSpringDamper>
  </gazebo>
  <link name="left_leg_l4">
    <inertial>
      <origin rpy="0 0 0" xyz="0.144283841094366 -0.00102279547401057 -0.0603084014166758"/>
      <mass value="0.562763238389391"/>
      <inertia ixx="0.00348790903629806" ixy="-6.72197320848768E-05" ixz="-2.20660425922105E-05" iyy="0.00918390431395075" iyz="5.28347099368345E-06" izz="0.00803159482751146"/>
    </inertial>
    <visual>
      <origin rpy="0 0 0" xyz="0 0 0"/>
      <geometry>
        <mesh filename="package://walker_description/meshes/left_leg_l4.STL"/>
      </geometry>
      <material name="">
        <color rgba="0.752941176470588 0.752941176470588 0.752941176470588 1"/>
      </material>
    </visual>
    <collision>
      <origin rpy="0 1.5708 0" xyz="0.220 -0.010 -0.060"/>
      <geometry>
        <cylinder length="0.240" radius="0.090"/>
      </geometry>
    </collision>
  </link>
  <gazebo reference="left_leg_l4">
    <!-- <selfCollide>true</selfCollide>-->
  </gazebo>
  <joint name="left_leg_j4" type="revolute">
    <origin rpy="-1.5708 1.2439E-10 -1.5708" xyz="0.062499 -0.18089 -0.011583"/>
    <parent link="left_leg_link1"/>
    <child link="left_leg_l4"/>
    <axis xyz="0 0 1"/>
    <limit effort="15.0" lower="-0.1745" upper="2.1817" velocity="3.1416"/>
    <dynamics damping="5.0" friction="0.0"/>
  </joint>
  <gazebo reference="left_leg_j4">
    <implicitSpringDamper>true</implicitSpringDamper>
  </gazebo>
  <link name="left_leg_l5">
    <inertial>
      <origin rpy="0 0 0" xyz="-8.21977772069715E-06 -0.00038477988471336 -0.000653186499701641"/>
      <mass value="0.273284460901946"/>
      <inertia ixx="0.00109932649823027" ixy="-3.62028115995012E-07" ixz="8.85639972401491E-08" iyy="0.00122863403306236" iyz="7.05340902748782E-07" izz="0.00151550242399035"/>
    </inertial>
    <visual>
      <origin rpy="0 0 0" xyz="0 0 0"/>
      <geometry>
        <mesh filename="package://walker_description/meshes/left_leg_l5.STL"/>
      </geometry>
      <material name="">
        <color rgba="0.752941176470588 0.752941176470588 0.752941176470588 1"/>
      </material>
    </visual>
    <!--<collision>
      <origin xyz="0 0 0" rpy="0 0 0" />
      <geometry>
        <cylinder length="0.110" radius="0.095"/>
      </geometry>
    </collision>-->
  </link>
  <gazebo reference="left_leg_l5">
    <!-- <selfCollide>true</selfCollide>-->
  </gazebo>
  <joint name="left_leg_j5" type="revolute">
    <origin rpy="-1.0408E-16 -3.8765E-15 -1.2439E-10" xyz="0.275 0 -0.0622"/>
    <parent link="left_leg_l4"/>
    <child link="left_leg_l5"/>
    <axis xyz="0 0 1"/>
    <limit effort="10.0" lower="-1.3963" upper="0.5236" velocity="3.1416"/>
    <dynamics damping="5.0" friction="0.5"/>
  </joint>
  <gazebo reference="left_leg_j5">
    <implicitSpringDamper>true</implicitSpringDamper>
  </gazebo>
  <link name="left_leg_l6">
    <inertial>
      <origin rpy="0 0 0" xyz="-8.21977772080817E-06 -0.000653186499701752 0.000384779884713304"/>
      <mass value="0.273284460901946"/>
      <inertia ixx="0.00109932649823027" ixy="8.85639972402066E-08" ixz="3.62028115995277E-07" iyy="0.00151550242399035" iyz="-7.05340902749039E-07" izz="0.00122863403306236"/>
    </inertial>
    <visual>
      <origin rpy="0 0 0" xyz="0 0 0"/>
      <geometry>
        <mesh filename="package://walker_description/meshes/left_leg_l6.STL"/>
      </geometry>
      <material name="">
        <color rgba="0.752941176470588 0.752941176470588 0.752941176470588 1"/>
      </material>
    </visual>
    <!--<collision>
      <origin xyz="0 0 0" rpy="1.5708 0 0" />
      <geometry>
        <cylinder length="0.110" radius="0.095"/>
      </geometry>
    </collision>-->
  </link>
  <gazebo reference="left_leg_l6">
    <!-- <selfCollide>true</selfCollide>-->
  </gazebo>
  <joint name="left_leg_j6" type="revolute">
    <origin rpy="1.5708 -1.0785E-32 0" xyz="0 0 0"/>
    <parent link="left_leg_l5"/>
    <child link="left_leg_l6"/>
    <axis xyz="0 0 1"/>
    <limit effort="10.0" lower="-0.5236" upper="0.5236" velocity="3.1416"/>
    <dynamics damping="5.0" friction="0.5"/>
  </joint>
  <gazebo reference="left_leg_j6">
    <implicitSpringDamper>true</implicitSpringDamper>
  </gazebo>
  <link name="left_leg_link2">
    <inertial>
      <origin rpy="0 0 0" xyz="5.34681040891272E-05 -0.0269451313812344 0.0158898260414049"/>
      <mass value="0.846568059732236"/>
      <inertia ixx="0.00616225237983881" ixy="1.08684830545345E-06" ixz="-1.6937518524817E-06" iyy="0.005633025666212" iyz="0.000156811758916288" izz="0.00283978255808244"/>
    </inertial>
    <visual>
      <origin rpy="0 0 0" xyz="0 0 0"/>
      <geometry>
        <mesh filename="package://walker_description/meshes/left_leg_link2.STL"/>
      </geometry>
      <material name="">
        <color rgba="0.752941176470588 0.752941176470588 0.752941176470588 1"/>
      </material>
    </visual>
    <collision>
      <origin rpy="0 0 0" xyz="0 -0.040 0.020"/>
      <geometry>
        <box size="0.140 0.060 0.250"/>
      </geometry>
    </collision>
  </link>
  <gazebo reference="left_leg_link2">
    <!-- <selfCollide>true</selfCollide>-->
  </gazebo>
  <joint name="left_leg_joint2" type="fixed">
    <origin rpy="-5.55111512312578E-17 -2.91796637638196E-16 1.5707963267949" xyz="0.0757484987958964 0 0"/>
    <parent link="left_leg_l6"/>
    <child link="left_leg_link2"/>
    <axis xyz="0 0 0"/>
  </joint>
  <gazebo reference="left_leg_joint2">
    <implicitSpringDamper>true</implicitSpringDamper>
  </gazebo>
  <transmission name="left_leg_tran1">
    <type>transmission_interface/SimpleTransmission</type>
    <joint name="left_leg_j1">
      <hardwareInterface>PositionJointInterface</hardwareInterface>
    </joint>
    <actuator name="left_leg_motor1">
      <hardwareInterface>PositionJointInterface</hardwareInterface>
      <mechanicalReduction>1</mechanicalReduction>
    </actuator>
  </transmission>
  <transmission name="left_leg_tran2">
    <type>transmission_interface/SimpleTransmission</type>
    <joint name="left_leg_j2">
      <hardwareInterface>PositionJointInterface</hardwareInterface>
    </joint>
    <actuator name="left_leg_motor2">
      <hardwareInterface>PositionJointInterface</hardwareInterface>
      <mechanicalReduction>1</mechanicalReduction>
    </actuator>
  </transmission>
  <transmission name="left_leg_tran3">
    <type>transmission_interface/SimpleTransmission</type>
    <joint name="left_leg_j3">
      <hardwareInterface>PositionJointInterface</hardwareInterface>
    </joint>
    <actuator name="left_leg_motor3">
      <hardwareInterface>PositionJointInterface</hardwareInterface>
      <mechanicalReduction>1</mechanicalReduction>
    </actuator>
  </transmission>
  <transmission name="left_leg_tran4">
    <type>transmission_interface/SimpleTransmission</type>
    <joint name="left_leg_j4">
      <hardwareInterface>PositionJointInterface</hardwareInterface>
    </joint>
    <actuator name="left_leg_motor4">
      <hardwareInterface>PositionJointInterface</hardwareInterface>
      <mechanicalReduction>1</mechanicalReduction>
    </actuator>
  </transmission>
  <transmission name="left_leg_tran5">
    <type>transmission_interface/SimpleTransmission</type>
    <joint name="left_leg_j5">
      <hardwareInterface>PositionJointInterface</hardwareInterface>
    </joint>
    <actuator name="left_leg_motor5">
      <hardwareInterface>PositionJointInterface</hardwareInterface>
      <mechanicalReduction>1</mechanicalReduction>
    </actuator>
  </transmission>
  <transmission name="left_leg_tran6">
    <type>transmission_interface/SimpleTransmission</type>
    <joint name="left_leg_j6">
      <hardwareInterface>PositionJointInterface</hardwareInterface>
    </joint>
    <actuator name="left_leg_motor6">
      <hardwareInterface>PositionJointInterface</hardwareInterface>
      <mechanicalReduction>1</mechanicalReduction>
    </actuator>
  </transmission>
  <link name="right_leg_l1">
    <inertial>
      <origin rpy="0 0 0" xyz="5.11129158978219E-06 -0.00936418225303887 -0.0512174036838659"/>
      <mass value="0.319858080834731"/>
      <inertia ixx="0.00254235658315077" ixy="1.57337755179459E-07" ixz="-6.66232939731674E-08" iyy="0.000943857580615831" iyz="4.82425859167378E-05" izz="0.0019715721917557"/>
    </inertial>
    <visual>
      <origin rpy="0 0 0" xyz="0 0 0"/>
      <geometry>
        <mesh filename="package://walker_description/meshes/right_leg_l1.STL"/>
      </geometry>
      <material name="">
        <color rgba="0.752941176470588 0.752941176470588 0.752941176470588 1"/>
      </material>
    </visual>
    <!--<collision>
      <origin xyz="0 0 0" rpy="0 1.5708 0" />
      <geometry>
        <cylinder length="0.105" radius="0.125"/>
      </geometry>
    </collision>-->
  </link>
  <gazebo reference="right_leg_l1">
    <!-- <selfCollide>true</selfCollide>-->
  </gazebo>
  <joint name="right_leg_j1" type="revolute">
    <origin rpy="-3.1416 0.0016575 -1.5708" xyz="0 -0.110 -0.43709"/>
    <parent link="base_link"/>
    <child link="right_leg_l1"/>
    <axis xyz="0 0 -1"/>
    <limit effort="30.0" lower="-1.0472" upper="1.0472" velocity="2.0944"/>
    <dynamics damping="15" friction="0.0"/>
  </joint>
  <gazebo reference="right_leg_j1">
    <implicitSpringDamper>true</implicitSpringDamper>
  </gazebo>
  <link name="right_leg_l2">
    <inertial>
      <origin rpy="0 0 0" xyz="-6.56335107418124E-06 -5.57679276523421E-05 -0.00164948243790175"/>
      <mass value="0.267364973444001"/>
      <inertia ixx="0.00124885275231294" ixy="-1.53186776629897E-07" ixz="1.42446831863807E-08" iyy="0.00186097534839342" iyz="1.0907298304675E-06" izz="0.00155483228633035"/>
    </inertial>
    <visual>
      <origin rpy="0 0 0" xyz="0 0 0"/>
      <geometry>
        <mesh filename="package://walker_description/meshes/right_leg_l2.STL"/>
      </geometry>
      <material name="">
        <color rgba="0.752941176470588 0.752941176470588 0.752941176470588 1"/>
      </material>
    </visual>
    <!--<collision>
      <origin xyz="0 0 0" rpy="1.5708 0 0" />
      <geometry>
        <cylinder length="0.120" radius="0.105"/>
      </geometry>
    </collision>-->
  </link>
  <gazebo reference="right_leg_l2">
    <!-- <selfCollide>true</selfCollide>-->
  </gazebo>
  <joint name="right_leg_j2" type="revolute">
    <origin rpy="1.5708 -1.5708 0" xyz="0 0 0"/>
    <parent link="right_leg_l1"/>
    <child link="right_leg_l2"/>
    <axis xyz="0 0 1"/>
    <limit effort="25.0" lower="-0.5236" upper="0.5236" velocity="3.1416"/>
    <dynamics damping="8.0" friction="0.0"/>
  </joint>
  <gazebo reference="right_leg_j2">
    <implicitSpringDamper>true</implicitSpringDamper>
  </gazebo>
  <link name="right_leg_l3">
    <inertial>
      <origin rpy="0 0 0" xyz="-6.56335107418818E-06 -0.00164948243790175 5.57679276523559E-05"/>
      <mass value="0.267364973444001"/>
      <inertia ixx="0.00124885275231294" ixy="1.42446831864238E-08" ixz="1.53186776629866E-07" iyy="0.00155483228633035" iyz="-1.09072983046752E-06" izz="0.00186097534839342"/>
    </inertial>
    <visual>
      <origin rpy="0 0 0" xyz="0 0 0"/>
      <geometry>
        <mesh filename="package://walker_description/meshes/right_leg_l3.STL"/>
      </geometry>
      <material name="">
        <color rgba="0.752941176470588 0.752941176470588 0.752941176470588 1"/>
      </material>
    </visual>
    <!--<collision>
      <origin xyz="0 0 0" rpy="0 0 0" />
      <geometry>
        <cylinder length="0.120" radius="0.105"/>
      </geometry>
    </collision>-->
  </link>
  <gazebo reference="right_leg_l3">
    <!-- <selfCollide>true</selfCollide>-->
  </gazebo>
  <joint name="right_leg_j3" type="revolute">
    <origin rpy="1.5708 0 -3.6455E-33" xyz="0 0 0"/>
    <parent link="right_leg_l2"/>
    <child link="right_leg_l3"/>
    <axis xyz="0 0 -1"/>
    <limit effort="15.0" lower="-1.3963" upper="0.5236" velocity="3.1416"/>
    <dynamics damping="5.0" friction="0.0"/>
  </joint>
  <gazebo reference="right_leg_j3">
    <implicitSpringDamper>true</implicitSpringDamper>
  </gazebo>
  <link name="right_leg_link1">
    <inertial>
      <origin rpy="0 0 0" xyz="-0.00142087955151143 0.0169322449435227 0.00185959311320971"/>
      <mass value="0.684322357309275"/>
      <inertia ixx="0.00954952360792742" ixy="-4.80368528637109E-05" ixz="-1.16597038259332E-05" iyy="0.00492713857542187" iyz="0.00020209353790523" izz="0.0117254451783956"/>
    </inertial>
    <visual>
      <origin rpy="0 0 0" xyz="0 0 0"/>
      <geometry>
        <mesh filename="package://walker_description/meshes/right_leg_link1.STL"/>
      </geometry>
      <material name="">
        <color rgba="0.752941176470588 0.752941176470588 0.752941176470588 1"/>
      </material>
    </visual>
    <collision>
      <origin rpy="1.5708 0 0" xyz="0 0.025 0"/>
      <geometry>
        <cylinder length="0.430" radius="0.090"/>
      </geometry>
    </collision>
  </link>
  <gazebo reference="right_leg_link1">
    <!-- <selfCollide>true</selfCollide>-->
  </gazebo>
  <joint name="right_leg_joint1" type="fixed">
    <origin rpy="1.5708 1.5708 0" xyz="0.10911 0.011583 -0.00047827"/>
    <parent link="right_leg_l3"/>
    <child link="right_leg_link1"/>
    <axis xyz="0 0 0"/>
  </joint>
  <gazebo reference="right_leg_joint1">
    <implicitSpringDamper>true</implicitSpringDamper>
  </gazebo>
  <link name="right_leg_l4">
    <inertial>
      <origin rpy="0 0 0" xyz="0.144364908610918 0.00102666849127719 -0.0602126138281589"/>
      <mass value="0.563191990876252"/>
      <inertia ixx="0.00349428616791089" ixy="6.68850844345436E-05" ixz="-2.34616900479645E-05" iyy="0.00919226857078181" iyz="-6.35361998638085E-06" izz="0.0080345870595671"/>
    </inertial>
    <visual>
      <origin rpy="0 0 0" xyz="0 0 0"/>
      <geometry>
        <mesh filename="package://walker_description/meshes/right_leg_l4.STL"/>
      </geometry>
      <material name="">
        <color rgba="0.752941176470588 0.752941176470588 0.752941176470588 1"/>
      </material>
    </visual>
    <collision>
      <origin rpy="0 1.5708 0" xyz="0.220 0 -0.060"/>
      <geometry>
        <cylinder length="0.240" radius="0.090"/>
      </geometry>
    </collision>
  </link>
  <gazebo reference="right_leg_l4">
    <!-- <selfCollide>true</selfCollide>-->
  </gazebo>
  <joint name="right_leg_j4" type="revolute">
    <origin rpy="-1.5708 -1.2439E-10 1.5708" xyz="-0.062478 0.18089 0.011583"/>
    <parent link="right_leg_link1"/>
    <child link="right_leg_l4"/>
    <axis xyz="0 0 -1"/>
    <limit effort="15.0" lower="-0.1745" upper="2.1817" velocity="3.1416"/>
    <dynamics damping="5.0" friction="0.0"/>
  </joint>
  <gazebo reference="right_leg_j4">
    <implicitSpringDamper>true</implicitSpringDamper>
  </gazebo>
  <link name="right_leg_l5">
    <inertial>
      <origin rpy="0 0 0" xyz="7.96335833541661E-06 0.000381749364422423 0.000653555695878147"/>
      <mass value="0.273290194984623"/>
      <inertia ixx="0.00109931070401539" ixy="-2.12453559703703E-07" ixz="9.96056672112059E-08" iyy="0.00122880276053965" iyz="7.33600925422293E-07" izz="0.00151564864910183"/>
    </inertial>
    <visual>
      <origin rpy="0 0 0" xyz="0 0 0"/>
      <geometry>
        <mesh filename="package://walker_description/meshes/right_leg_l5.STL"/>
      </geometry>
      <material name="">
        <color rgba="0.752941176470588 0.752941176470588 0.752941176470588 1"/>
      </material>
    </visual>
    <!--<collision>
      <origin xyz="0 0 0" rpy="0 0 0" />
      <geometry>
        <cylinder length="0.110" radius="0.095"/>
      </geometry>
    </collision>-->
  </link>
  <gazebo reference="right_leg_l5">
    <!-- <selfCollide>true</selfCollide>-->
  </gazebo>
  <joint name="right_leg_j5" type="revolute">
    <origin rpy="-2.4228E-16 -7.0505E-30 -2.4021E-16" xyz="0.275 0 -0.0622"/>
    <parent link="right_leg_l4"/>
    <child link="right_leg_l5"/>
    <axis xyz="0 0 -1"/>
    <limit effort="10.0" lower="-1.3963" upper="0.5236" velocity="3.1416"/>
    <dynamics damping="5.0" friction="0.5"/>
  </joint>
  <gazebo reference="right_leg_j5">
    <implicitSpringDamper>true</implicitSpringDamper>
  </gazebo>
  <link name="right_leg_l6">
    <inertial>
      <origin rpy="0 0 0" xyz="7.96335833541661E-06 -0.000653555695878147 0.000381749364422423"/>
      <mass value="0.273290194984624"/>
      <inertia ixx="0.00109931070401539" ixy="-9.96056672112108E-08" ixz="-2.12453559703108E-07" iyy="0.00151564864910183" iyz="-7.3360092542231E-07" izz="0.00122880276053965"/>
    </inertial>
    <visual>
      <origin rpy="0 0 0" xyz="0 0 0"/>
      <geometry>
        <mesh filename="package://walker_description/meshes/right_leg_l6.STL"/>
      </geometry>
      <material name="">
        <color rgba="0.752941176470588 0.752941176470588 0.752941176470588 1"/>
      </material>
    </visual>
    <!--<collision>
      <origin xyz="0 0 0" rpy="1.5708 0 0" />
      <geometry>
        <cylinder length="0.110" radius="0.095"/>
      </geometry>
    </collision>-->
  </link>
  <gazebo reference="right_leg_l6">
    <!-- <selfCollide>true</selfCollide>-->
  </gazebo>
  <joint name="right_leg_j6" type="revolute">
    <origin rpy="-1.5708 2.1861E-32 0" xyz="0 0 0"/>
    <parent link="right_leg_l5"/>
    <child link="right_leg_l6"/>
    <axis xyz="0 0 1"/>
    <limit effort="10.0" lower="-0.5236" upper="0.5236" velocity="3.1416"/>
    <dynamics damping="5.0" friction="0.5"/>
  </joint>
  <gazebo reference="right_leg_j6">
    <implicitSpringDamper>true</implicitSpringDamper>
  </gazebo>
  <link name="right_leg_link2">
    <inertial>
      <origin rpy="0 0 0" xyz="5.34466089641278E-05 -0.0271413448383175 0.015889818192348"/>
      <mass value="0.846568539228478"/>
      <inertia ixx="0.00616159172023952" ixy="1.09312906490746E-06" ixz="-1.69420307973642E-06" iyy="0.00563302608024886" iyz="0.000157121150126079" izz="0.00283912246047331"/>
    </inertial>
    <visual>
      <origin rpy="0 0 0" xyz="0 0 0"/>
      <geometry>
        <mesh filename="package://walker_description/meshes/right_leg_link2.STL"/>
      </geometry>
      <material name="">
        <color rgba="0.752941176470588 0.752941176470588 0.752941176470588 1"/>
      </material>
    </visual>
    <collision>
      <origin rpy="0 0 0" xyz="0 -0.040 0.020"/>
      <geometry>
        <box size="0.140 0.060 0.250"/>
      </geometry>
    </collision>
  </link>
  <gazebo reference="right_leg_link2">
    <!-- <selfCollide>true</selfCollide>-->
  </gazebo>
  <joint name="right_leg_joint2" type="fixed">
    <origin rpy="-1.2439E-10 -1.3298E-16 1.5708" xyz="0.075748 0 0"/>
    <parent link="right_leg_l6"/>
    <child link="right_leg_link2"/>
    <axis xyz="0 0 0"/>
  </joint>
  <gazebo reference="right_leg_joint2">
    <implicitSpringDamper>true</implicitSpringDamper>
  </gazebo>
  <transmission name="right_leg_tran1">
    <type>transmission_interface/SimpleTransmission</type>
    <joint name="right_leg_j1">
      <hardwareInterface>PositionJointInterface</hardwareInterface>
    </joint>
    <actuator name="right_leg_motor1">
      <hardwareInterface>PositionJointInterface</hardwareInterface>
      <mechanicalReduction>1</mechanicalReduction>
    </actuator>
  </transmission>
  <transmission name="right_leg_tran2">
    <type>transmission_interface/SimpleTransmission</type>
    <joint name="right_leg_j2">
      <hardwareInterface>PositionJointInterface</hardwareInterface>
    </joint>
    <actuator name="right_leg_motor2">
      <hardwareInterface>PositionJointInterface</hardwareInterface>
      <mechanicalReduction>1</mechanicalReduction>
    </actuator>
  </transmission>
  <transmission name="right_leg_tran3">
    <type>transmission_interface/SimpleTransmission</type>
    <joint name="right_leg_j3">
      <hardwareInterface>PositionJointInterface</hardwareInterface>
    </joint>
    <actuator name="right_leg_motor3">
      <hardwareInterface>PositionJointInterface</hardwareInterface>
      <mechanicalReduction>1</mechanicalReduction>
    </actuator>
  </transmission>
  <transmission name="right_leg_tran4">
    <type>transmission_interface/SimpleTransmission</type>
    <joint name="right_leg_j4">
      <hardwareInterface>PositionJointInterface</hardwareInterface>
    </joint>
    <actuator name="right_leg_motor4">
      <hardwareInterface>PositionJointInterface</hardwareInterface>
      <mechanicalReduction>1</mechanicalReduction>
    </actuator>
  </transmission>
  <transmission name="right_leg_tran5">
    <type>transmission_interface/SimpleTransmission</type>
    <joint name="right_leg_j5">
      <hardwareInterface>PositionJointInterface</hardwareInterface>
    </joint>
    <actuator name="right_leg_motor5">
      <hardwareInterface>PositionJointInterface</hardwareInterface>
      <mechanicalReduction>1</mechanicalReduction>
    </actuator>
  </transmission>
  <transmission name="right_leg_tran6">
    <type>transmission_interface/SimpleTransmission</type>
    <joint name="right_leg_j6">
      <hardwareInterface>PositionJointInterface</hardwareInterface>
    </joint>
    <actuator name="right_leg_motor6">
      <hardwareInterface>PositionJointInterface</hardwareInterface>
      <mechanicalReduction>1</mechanicalReduction>
    </actuator>
  </transmission>
</robot>

